2024-03-07 13:06:06 | WARNING | Api Key is missing or invalid
2024-03-07 13:06:33 | WARNING | Api Key is missing or invalid
2024-05-09 12:28:21 | WARNING | Api Key is missing or invalid
2024-05-09 12:36:37 | WARNING | Api Key is missing or invalid
2024-05-09 12:36:53 | WARNING | Api Key is missing or invalid
2024-05-09 12:37:19 | WARNING | Api Key is missing or invalid
2024-05-09 15:04:10 | WARNING | Api Key is missing or invalid
2024-05-09 15:04:13 | WARNING | Api Key is missing or invalid
2024-05-09 15:06:09 | WARNING | Api Key is missing or invalid
2024-05-09 15:22:34 | WARNING | Api Key is missing or invalid
2024-05-09 15:48:15 | WARNING | Api Key is missing or invalid
2024-05-10 08:20:13 | ERROR | PeopleService.get_all() missing 1 required positional argument: 'self'
2024-05-10 08:20:44 | ERROR | (2003, "Can't connect to MySQL server on 'mysql' ([Errno 8] nodename nor servname provided, or not known)")
2024-05-10 08:20:44 | ERROR | Traceback (most recent call last):
  File "/Library/Frameworks/Python.framework/Versions/3.12/lib/python3.12/site-packages/pymysql/connections.py", line 644, in connect
    sock = socket.create_connection(
           ^^^^^^^^^^^^^^^^^^^^^^^^^
  File "/Library/Frameworks/Python.framework/Versions/3.12/lib/python3.12/socket.py", line 828, in create_connection
    for res in getaddrinfo(host, port, 0, SOCK_STREAM):
               ^^^^^^^^^^^^^^^^^^^^^^^^^^^^^^^^^^^^^^^
  File "/Library/Frameworks/Python.framework/Versions/3.12/lib/python3.12/socket.py", line 963, in getaddrinfo
    for res in _socket.getaddrinfo(host, port, family, type, proto, flags):
               ^^^^^^^^^^^^^^^^^^^^^^^^^^^^^^^^^^^^^^^^^^^^^^^^^^^^^^^^^^^
socket.gaierror: [Errno 8] nodename nor servname provided, or not known

During handling of the above exception, another exception occurred:

Traceback (most recent call last):
  File "/Users/ulisesv/Desktop/chewbacca/backend/api/src/database/db_mysql.py", line 9, in get_connection
    return pymysql.connect(
           ^^^^^^^^^^^^^^^^
  File "/Library/Frameworks/Python.framework/Versions/3.12/lib/python3.12/site-packages/pymysql/connections.py", line 358, in __init__
    self.connect()
  File "/Library/Frameworks/Python.framework/Versions/3.12/lib/python3.12/site-packages/pymysql/connections.py", line 711, in connect
    raise exc
pymysql.err.OperationalError: (2003, "Can't connect to MySQL server on 'mysql' ([Errno 8] nodename nor servname provided, or not known)")

2024-05-10 08:20:44 | ERROR | 'NoneType' object has no attribute 'cursor'
2024-05-10 08:42:35 | ERROR | type object 'PeopleService' has no attribute 'get_all'
2024-05-10 08:43:11 | ERROR | (2003, "Can't connect to MySQL server on 'mysql' ([Errno 8] nodename nor servname provided, or not known)")
2024-05-10 08:43:11 | ERROR | Traceback (most recent call last):
  File "/Library/Frameworks/Python.framework/Versions/3.12/lib/python3.12/site-packages/pymysql/connections.py", line 644, in connect
    sock = socket.create_connection(
           ^^^^^^^^^^^^^^^^^^^^^^^^^
  File "/Library/Frameworks/Python.framework/Versions/3.12/lib/python3.12/socket.py", line 828, in create_connection
    for res in getaddrinfo(host, port, 0, SOCK_STREAM):
               ^^^^^^^^^^^^^^^^^^^^^^^^^^^^^^^^^^^^^^^
  File "/Library/Frameworks/Python.framework/Versions/3.12/lib/python3.12/socket.py", line 963, in getaddrinfo
    for res in _socket.getaddrinfo(host, port, family, type, proto, flags):
               ^^^^^^^^^^^^^^^^^^^^^^^^^^^^^^^^^^^^^^^^^^^^^^^^^^^^^^^^^^^
socket.gaierror: [Errno 8] nodename nor servname provided, or not known

During handling of the above exception, another exception occurred:

Traceback (most recent call last):
  File "/Users/ulisesv/Desktop/chewbacca/backend/api/src/database/db_mysql.py", line 9, in get_connection
    return pymysql.connect(
           ^^^^^^^^^^^^^^^^
  File "/Library/Frameworks/Python.framework/Versions/3.12/lib/python3.12/site-packages/pymysql/connections.py", line 358, in __init__
    self.connect()
  File "/Library/Frameworks/Python.framework/Versions/3.12/lib/python3.12/site-packages/pymysql/connections.py", line 711, in connect
    raise exc
pymysql.err.OperationalError: (2003, "Can't connect to MySQL server on 'mysql' ([Errno 8] nodename nor servname provided, or not known)")

2024-05-10 08:43:11 | ERROR | name 'Logger' is not defined
2024-05-10 08:44:05 | ERROR | (2003, "Can't connect to MySQL server on 'mysql' ([Errno 8] nodename nor servname provided, or not known)")
2024-05-10 08:44:05 | ERROR | Traceback (most recent call last):
  File "/Library/Frameworks/Python.framework/Versions/3.12/lib/python3.12/site-packages/pymysql/connections.py", line 644, in connect
    sock = socket.create_connection(
           ^^^^^^^^^^^^^^^^^^^^^^^^^
  File "/Library/Frameworks/Python.framework/Versions/3.12/lib/python3.12/socket.py", line 828, in create_connection
    for res in getaddrinfo(host, port, 0, SOCK_STREAM):
               ^^^^^^^^^^^^^^^^^^^^^^^^^^^^^^^^^^^^^^^
  File "/Library/Frameworks/Python.framework/Versions/3.12/lib/python3.12/socket.py", line 963, in getaddrinfo
    for res in _socket.getaddrinfo(host, port, family, type, proto, flags):
               ^^^^^^^^^^^^^^^^^^^^^^^^^^^^^^^^^^^^^^^^^^^^^^^^^^^^^^^^^^^
socket.gaierror: [Errno 8] nodename nor servname provided, or not known

During handling of the above exception, another exception occurred:

Traceback (most recent call last):
  File "/Users/ulisesv/Desktop/chewbacca/backend/api/src/database/db_mysql.py", line 9, in get_connection
    return pymysql.connect(
           ^^^^^^^^^^^^^^^^
  File "/Library/Frameworks/Python.framework/Versions/3.12/lib/python3.12/site-packages/pymysql/connections.py", line 358, in __init__
    self.connect()
  File "/Library/Frameworks/Python.framework/Versions/3.12/lib/python3.12/site-packages/pymysql/connections.py", line 711, in connect
    raise exc
pymysql.err.OperationalError: (2003, "Can't connect to MySQL server on 'mysql' ([Errno 8] nodename nor servname provided, or not known)")

2024-05-10 08:44:05 | ERROR | 'NoneType' object has no attribute 'cursor'
2024-05-10 08:44:05 | ERROR | name 'traceback' is not defined
2024-05-10 08:44:28 | ERROR | (2003, "Can't connect to MySQL server on 'mysql' ([Errno 8] nodename nor servname provided, or not known)")
2024-05-10 08:44:28 | ERROR | Traceback (most recent call last):
  File "/Library/Frameworks/Python.framework/Versions/3.12/lib/python3.12/site-packages/pymysql/connections.py", line 644, in connect
    sock = socket.create_connection(
           ^^^^^^^^^^^^^^^^^^^^^^^^^
  File "/Library/Frameworks/Python.framework/Versions/3.12/lib/python3.12/socket.py", line 828, in create_connection
    for res in getaddrinfo(host, port, 0, SOCK_STREAM):
               ^^^^^^^^^^^^^^^^^^^^^^^^^^^^^^^^^^^^^^^
  File "/Library/Frameworks/Python.framework/Versions/3.12/lib/python3.12/socket.py", line 963, in getaddrinfo
    for res in _socket.getaddrinfo(host, port, family, type, proto, flags):
               ^^^^^^^^^^^^^^^^^^^^^^^^^^^^^^^^^^^^^^^^^^^^^^^^^^^^^^^^^^^
socket.gaierror: [Errno 8] nodename nor servname provided, or not known

During handling of the above exception, another exception occurred:

Traceback (most recent call last):
  File "/Users/ulisesv/Desktop/chewbacca/backend/api/src/database/db_mysql.py", line 9, in get_connection
    return pymysql.connect(
           ^^^^^^^^^^^^^^^^
  File "/Library/Frameworks/Python.framework/Versions/3.12/lib/python3.12/site-packages/pymysql/connections.py", line 358, in __init__
    self.connect()
  File "/Library/Frameworks/Python.framework/Versions/3.12/lib/python3.12/site-packages/pymysql/connections.py", line 711, in connect
    raise exc
pymysql.err.OperationalError: (2003, "Can't connect to MySQL server on 'mysql' ([Errno 8] nodename nor servname provided, or not known)")

2024-05-10 08:44:28 | ERROR | 'NoneType' object has no attribute 'cursor'
2024-05-10 08:44:28 | ERROR | Traceback (most recent call last):
  File "/Users/ulisesv/Desktop/chewbacca/backend/api/src/services/people.py", line 14, in get_people
    results = get_people_pagination(page)
              ^^^^^^^^^^^^^^^^^^^^^^^^^^^
  File "/Users/ulisesv/Desktop/chewbacca/backend/api/src/controllers/people.py", line 27, in get_people_pagination
    with conexion.cursor() as cursor:
         ^^^^^^^^^^^^^^^
AttributeError: 'NoneType' object has no attribute 'cursor'

2024-05-10 08:45:18 | ERROR | (2003, "Can't connect to MySQL server on 'mysql' ([Errno 8] nodename nor servname provided, or not known)")
2024-05-10 08:45:18 | ERROR | Traceback (most recent call last):
  File "/Library/Frameworks/Python.framework/Versions/3.12/lib/python3.12/site-packages/pymysql/connections.py", line 644, in connect
    sock = socket.create_connection(
           ^^^^^^^^^^^^^^^^^^^^^^^^^
  File "/Library/Frameworks/Python.framework/Versions/3.12/lib/python3.12/socket.py", line 828, in create_connection
    for res in getaddrinfo(host, port, 0, SOCK_STREAM):
               ^^^^^^^^^^^^^^^^^^^^^^^^^^^^^^^^^^^^^^^
  File "/Library/Frameworks/Python.framework/Versions/3.12/lib/python3.12/socket.py", line 963, in getaddrinfo
    for res in _socket.getaddrinfo(host, port, family, type, proto, flags):
               ^^^^^^^^^^^^^^^^^^^^^^^^^^^^^^^^^^^^^^^^^^^^^^^^^^^^^^^^^^^
socket.gaierror: [Errno 8] nodename nor servname provided, or not known

During handling of the above exception, another exception occurred:

Traceback (most recent call last):
  File "/Users/ulisesv/Desktop/chewbacca/backend/api/src/database/db_mysql.py", line 9, in get_connection
    return pymysql.connect(
           ^^^^^^^^^^^^^^^^
  File "/Library/Frameworks/Python.framework/Versions/3.12/lib/python3.12/site-packages/pymysql/connections.py", line 358, in __init__
    self.connect()
  File "/Library/Frameworks/Python.framework/Versions/3.12/lib/python3.12/site-packages/pymysql/connections.py", line 711, in connect
    raise exc
pymysql.err.OperationalError: (2003, "Can't connect to MySQL server on 'mysql' ([Errno 8] nodename nor servname provided, or not known)")

2024-05-10 08:45:18 | ERROR | 'NoneType' object has no attribute 'cursor'
2024-05-10 08:45:18 | ERROR | Traceback (most recent call last):
  File "/Users/ulisesv/Desktop/chewbacca/backend/api/src/services/people.py", line 14, in get_people
    results = get_people_pagination(page)
              ^^^^^^^^^^^^^^^^^^^^^^^^^^^
  File "/Users/ulisesv/Desktop/chewbacca/backend/api/src/controllers/people.py", line 27, in get_people_pagination
    with conexion.cursor() as cursor:
         ^^^^^^^^^^^^^^^
AttributeError: 'NoneType' object has no attribute 'cursor'

2024-05-10 08:45:19 | ERROR | (2003, "Can't connect to MySQL server on 'mysql' ([Errno 8] nodename nor servname provided, or not known)")
2024-05-10 08:45:19 | ERROR | Traceback (most recent call last):
  File "/Library/Frameworks/Python.framework/Versions/3.12/lib/python3.12/site-packages/pymysql/connections.py", line 644, in connect
    sock = socket.create_connection(
           ^^^^^^^^^^^^^^^^^^^^^^^^^
  File "/Library/Frameworks/Python.framework/Versions/3.12/lib/python3.12/socket.py", line 828, in create_connection
    for res in getaddrinfo(host, port, 0, SOCK_STREAM):
               ^^^^^^^^^^^^^^^^^^^^^^^^^^^^^^^^^^^^^^^
  File "/Library/Frameworks/Python.framework/Versions/3.12/lib/python3.12/socket.py", line 963, in getaddrinfo
    for res in _socket.getaddrinfo(host, port, family, type, proto, flags):
               ^^^^^^^^^^^^^^^^^^^^^^^^^^^^^^^^^^^^^^^^^^^^^^^^^^^^^^^^^^^
socket.gaierror: [Errno 8] nodename nor servname provided, or not known

During handling of the above exception, another exception occurred:

Traceback (most recent call last):
  File "/Users/ulisesv/Desktop/chewbacca/backend/api/src/database/db_mysql.py", line 9, in get_connection
    return pymysql.connect(
           ^^^^^^^^^^^^^^^^
  File "/Library/Frameworks/Python.framework/Versions/3.12/lib/python3.12/site-packages/pymysql/connections.py", line 358, in __init__
    self.connect()
  File "/Library/Frameworks/Python.framework/Versions/3.12/lib/python3.12/site-packages/pymysql/connections.py", line 711, in connect
    raise exc
pymysql.err.OperationalError: (2003, "Can't connect to MySQL server on 'mysql' ([Errno 8] nodename nor servname provided, or not known)")

2024-05-10 08:45:19 | ERROR | 'NoneType' object has no attribute 'cursor'
2024-05-10 08:45:19 | ERROR | Traceback (most recent call last):
  File "/Users/ulisesv/Desktop/chewbacca/backend/api/src/services/people.py", line 14, in get_people
    results = get_people_pagination(page)
              ^^^^^^^^^^^^^^^^^^^^^^^^^^^
  File "/Users/ulisesv/Desktop/chewbacca/backend/api/src/controllers/people.py", line 27, in get_people_pagination
    with conexion.cursor() as cursor:
         ^^^^^^^^^^^^^^^
AttributeError: 'NoneType' object has no attribute 'cursor'

2024-05-10 08:45:40 | ERROR | (2003, "Can't connect to MySQL server on 'mysql' ([Errno 8] nodename nor servname provided, or not known)")
2024-05-10 08:45:40 | ERROR | Traceback (most recent call last):
  File "/Library/Frameworks/Python.framework/Versions/3.12/lib/python3.12/site-packages/pymysql/connections.py", line 644, in connect
    sock = socket.create_connection(
           ^^^^^^^^^^^^^^^^^^^^^^^^^
  File "/Library/Frameworks/Python.framework/Versions/3.12/lib/python3.12/socket.py", line 828, in create_connection
    for res in getaddrinfo(host, port, 0, SOCK_STREAM):
               ^^^^^^^^^^^^^^^^^^^^^^^^^^^^^^^^^^^^^^^
  File "/Library/Frameworks/Python.framework/Versions/3.12/lib/python3.12/socket.py", line 963, in getaddrinfo
    for res in _socket.getaddrinfo(host, port, family, type, proto, flags):
               ^^^^^^^^^^^^^^^^^^^^^^^^^^^^^^^^^^^^^^^^^^^^^^^^^^^^^^^^^^^
socket.gaierror: [Errno 8] nodename nor servname provided, or not known

During handling of the above exception, another exception occurred:

Traceback (most recent call last):
  File "/Users/ulisesv/Desktop/chewbacca/backend/api/src/database/db_mysql.py", line 9, in get_connection
    return pymysql.connect(
           ^^^^^^^^^^^^^^^^
  File "/Library/Frameworks/Python.framework/Versions/3.12/lib/python3.12/site-packages/pymysql/connections.py", line 358, in __init__
    self.connect()
  File "/Library/Frameworks/Python.framework/Versions/3.12/lib/python3.12/site-packages/pymysql/connections.py", line 711, in connect
    raise exc
pymysql.err.OperationalError: (2003, "Can't connect to MySQL server on 'mysql' ([Errno 8] nodename nor servname provided, or not known)")

2024-05-10 08:45:40 | ERROR | 'NoneType' object has no attribute 'cursor'
2024-05-10 08:45:40 | ERROR | Traceback (most recent call last):
  File "/Users/ulisesv/Desktop/chewbacca/backend/api/src/services/people.py", line 14, in get_people
    results = get_people_pagination(page)
              ^^^^^^^^^^^^^^^^^^^^^^^^^^^
  File "/Users/ulisesv/Desktop/chewbacca/backend/api/src/controllers/people.py", line 27, in get_people_pagination
    with conexion.cursor() as cursor:
         ^^^^^^^^^^^^^^^
AttributeError: 'NoneType' object has no attribute 'cursor'

2024-05-10 08:51:34 | ERROR | (2003, "Can't connect to MySQL server on 'mysql' ([Errno 8] nodename nor servname provided, or not known)")
2024-05-10 08:51:34 | ERROR | Traceback (most recent call last):
  File "/Library/Frameworks/Python.framework/Versions/3.12/lib/python3.12/site-packages/pymysql/connections.py", line 644, in connect
    sock = socket.create_connection(
           ^^^^^^^^^^^^^^^^^^^^^^^^^
  File "/Library/Frameworks/Python.framework/Versions/3.12/lib/python3.12/socket.py", line 828, in create_connection
    for res in getaddrinfo(host, port, 0, SOCK_STREAM):
               ^^^^^^^^^^^^^^^^^^^^^^^^^^^^^^^^^^^^^^^
  File "/Library/Frameworks/Python.framework/Versions/3.12/lib/python3.12/socket.py", line 963, in getaddrinfo
    for res in _socket.getaddrinfo(host, port, family, type, proto, flags):
               ^^^^^^^^^^^^^^^^^^^^^^^^^^^^^^^^^^^^^^^^^^^^^^^^^^^^^^^^^^^
socket.gaierror: [Errno 8] nodename nor servname provided, or not known

During handling of the above exception, another exception occurred:

Traceback (most recent call last):
  File "/Users/ulisesv/Desktop/chewbacca/backend/api/src/database/db_mysql.py", line 9, in get_connection
    return pymysql.connect(
           ^^^^^^^^^^^^^^^^
  File "/Library/Frameworks/Python.framework/Versions/3.12/lib/python3.12/site-packages/pymysql/connections.py", line 358, in __init__
    self.connect()
  File "/Library/Frameworks/Python.framework/Versions/3.12/lib/python3.12/site-packages/pymysql/connections.py", line 711, in connect
    raise exc
pymysql.err.OperationalError: (2003, "Can't connect to MySQL server on 'mysql' ([Errno 8] nodename nor servname provided, or not known)")

2024-05-10 08:51:34 | ERROR | 'NoneType' object has no attribute 'cursor'
2024-05-10 08:51:34 | ERROR | Traceback (most recent call last):
  File "/Users/ulisesv/Desktop/chewbacca/backend/api/src/services/people.py", line 14, in get_people
    results = get_people_pagination(page)
              ^^^^^^^^^^^^^^^^^^^^^^^^^^^
  File "/Users/ulisesv/Desktop/chewbacca/backend/api/src/controllers/people.py", line 27, in get_people_pagination
    with conexion.cursor() as cursor:
         ^^^^^^^^^^^^^^^
AttributeError: 'NoneType' object has no attribute 'cursor'

2024-05-10 08:51:37 | ERROR | (2003, "Can't connect to MySQL server on 'mysql' ([Errno 8] nodename nor servname provided, or not known)")
2024-05-10 08:51:37 | ERROR | Traceback (most recent call last):
  File "/Library/Frameworks/Python.framework/Versions/3.12/lib/python3.12/site-packages/pymysql/connections.py", line 644, in connect
    sock = socket.create_connection(
           ^^^^^^^^^^^^^^^^^^^^^^^^^
  File "/Library/Frameworks/Python.framework/Versions/3.12/lib/python3.12/socket.py", line 828, in create_connection
    for res in getaddrinfo(host, port, 0, SOCK_STREAM):
               ^^^^^^^^^^^^^^^^^^^^^^^^^^^^^^^^^^^^^^^
  File "/Library/Frameworks/Python.framework/Versions/3.12/lib/python3.12/socket.py", line 963, in getaddrinfo
    for res in _socket.getaddrinfo(host, port, family, type, proto, flags):
               ^^^^^^^^^^^^^^^^^^^^^^^^^^^^^^^^^^^^^^^^^^^^^^^^^^^^^^^^^^^
socket.gaierror: [Errno 8] nodename nor servname provided, or not known

During handling of the above exception, another exception occurred:

Traceback (most recent call last):
  File "/Users/ulisesv/Desktop/chewbacca/backend/api/src/database/db_mysql.py", line 9, in get_connection
    return pymysql.connect(
           ^^^^^^^^^^^^^^^^
  File "/Library/Frameworks/Python.framework/Versions/3.12/lib/python3.12/site-packages/pymysql/connections.py", line 358, in __init__
    self.connect()
  File "/Library/Frameworks/Python.framework/Versions/3.12/lib/python3.12/site-packages/pymysql/connections.py", line 711, in connect
    raise exc
pymysql.err.OperationalError: (2003, "Can't connect to MySQL server on 'mysql' ([Errno 8] nodename nor servname provided, or not known)")

2024-05-10 08:51:37 | ERROR | 'NoneType' object has no attribute 'cursor'
2024-05-10 08:51:37 | ERROR | Traceback (most recent call last):
  File "/Users/ulisesv/Desktop/chewbacca/backend/api/src/services/people.py", line 14, in get_people
    results = get_people_pagination(page)
              ^^^^^^^^^^^^^^^^^^^^^^^^^^^
  File "/Users/ulisesv/Desktop/chewbacca/backend/api/src/controllers/people.py", line 27, in get_people_pagination
    with conexion.cursor() as cursor:
         ^^^^^^^^^^^^^^^
AttributeError: 'NoneType' object has no attribute 'cursor'

2024-05-10 08:52:45 | ERROR | (2003, "Can't connect to MySQL server on 'mysql' ([Errno 8] nodename nor servname provided, or not known)")
2024-05-10 08:52:45 | ERROR | Traceback (most recent call last):
  File "/Library/Frameworks/Python.framework/Versions/3.12/lib/python3.12/site-packages/pymysql/connections.py", line 644, in connect
    sock = socket.create_connection(
           ^^^^^^^^^^^^^^^^^^^^^^^^^
  File "/Library/Frameworks/Python.framework/Versions/3.12/lib/python3.12/socket.py", line 828, in create_connection
    for res in getaddrinfo(host, port, 0, SOCK_STREAM):
               ^^^^^^^^^^^^^^^^^^^^^^^^^^^^^^^^^^^^^^^
  File "/Library/Frameworks/Python.framework/Versions/3.12/lib/python3.12/socket.py", line 963, in getaddrinfo
    for res in _socket.getaddrinfo(host, port, family, type, proto, flags):
               ^^^^^^^^^^^^^^^^^^^^^^^^^^^^^^^^^^^^^^^^^^^^^^^^^^^^^^^^^^^
socket.gaierror: [Errno 8] nodename nor servname provided, or not known

During handling of the above exception, another exception occurred:

Traceback (most recent call last):
  File "/Users/ulisesv/Desktop/chewbacca/backend/api/src/database/db_mysql.py", line 9, in get_connection
    return pymysql.connect(
           ^^^^^^^^^^^^^^^^
  File "/Library/Frameworks/Python.framework/Versions/3.12/lib/python3.12/site-packages/pymysql/connections.py", line 358, in __init__
    self.connect()
  File "/Library/Frameworks/Python.framework/Versions/3.12/lib/python3.12/site-packages/pymysql/connections.py", line 711, in connect
    raise exc
pymysql.err.OperationalError: (2003, "Can't connect to MySQL server on 'mysql' ([Errno 8] nodename nor servname provided, or not known)")

2024-05-10 08:52:45 | ERROR | 'NoneType' object has no attribute 'cursor'
2024-05-10 08:52:45 | ERROR | Traceback (most recent call last):
  File "/Users/ulisesv/Desktop/chewbacca/backend/api/src/services/people.py", line 14, in get_people
    results = get_people_pagination(page)
              ^^^^^^^^^^^^^^^^^^^^^^^^^^^
  File "/Users/ulisesv/Desktop/chewbacca/backend/api/src/controllers/people.py", line 27, in get_people_pagination
    with conexion.cursor() as cursor:
         ^^^^^^^^^^^^^^^
AttributeError: 'NoneType' object has no attribute 'cursor'

2024-05-10 08:53:00 | ERROR | (2003, "Can't connect to MySQL server on 'mysql' ([Errno 8] nodename nor servname provided, or not known)")
2024-05-10 08:53:00 | ERROR | Traceback (most recent call last):
  File "/Library/Frameworks/Python.framework/Versions/3.12/lib/python3.12/site-packages/pymysql/connections.py", line 644, in connect
    sock = socket.create_connection(
           ^^^^^^^^^^^^^^^^^^^^^^^^^
  File "/Library/Frameworks/Python.framework/Versions/3.12/lib/python3.12/socket.py", line 828, in create_connection
    for res in getaddrinfo(host, port, 0, SOCK_STREAM):
               ^^^^^^^^^^^^^^^^^^^^^^^^^^^^^^^^^^^^^^^
  File "/Library/Frameworks/Python.framework/Versions/3.12/lib/python3.12/socket.py", line 963, in getaddrinfo
    for res in _socket.getaddrinfo(host, port, family, type, proto, flags):
               ^^^^^^^^^^^^^^^^^^^^^^^^^^^^^^^^^^^^^^^^^^^^^^^^^^^^^^^^^^^
socket.gaierror: [Errno 8] nodename nor servname provided, or not known

During handling of the above exception, another exception occurred:

Traceback (most recent call last):
  File "/Users/ulisesv/Desktop/chewbacca/backend/api/src/database/db_mysql.py", line 9, in get_connection
    return pymysql.connect(
           ^^^^^^^^^^^^^^^^
  File "/Library/Frameworks/Python.framework/Versions/3.12/lib/python3.12/site-packages/pymysql/connections.py", line 358, in __init__
    self.connect()
  File "/Library/Frameworks/Python.framework/Versions/3.12/lib/python3.12/site-packages/pymysql/connections.py", line 711, in connect
    raise exc
pymysql.err.OperationalError: (2003, "Can't connect to MySQL server on 'mysql' ([Errno 8] nodename nor servname provided, or not known)")

2024-05-10 08:53:00 | ERROR | 'NoneType' object has no attribute 'cursor'
2024-05-10 08:53:00 | ERROR | Traceback (most recent call last):
  File "/Users/ulisesv/Desktop/chewbacca/backend/api/src/services/people.py", line 14, in get_people
    results = get_people_pagination(page)
              ^^^^^^^^^^^^^^^^^^^^^^^^^^^
  File "/Users/ulisesv/Desktop/chewbacca/backend/api/src/controllers/people.py", line 27, in get_people_pagination
    with conexion.cursor() as cursor:
         ^^^^^^^^^^^^^^^
AttributeError: 'NoneType' object has no attribute 'cursor'

2024-05-10 08:53:12 | ERROR | (2003, "Can't connect to MySQL server on 'mysql' ([Errno 8] nodename nor servname provided, or not known)")
2024-05-10 08:53:12 | ERROR | Traceback (most recent call last):
  File "/Library/Frameworks/Python.framework/Versions/3.12/lib/python3.12/site-packages/pymysql/connections.py", line 644, in connect
    sock = socket.create_connection(
           ^^^^^^^^^^^^^^^^^^^^^^^^^
  File "/Library/Frameworks/Python.framework/Versions/3.12/lib/python3.12/socket.py", line 828, in create_connection
    for res in getaddrinfo(host, port, 0, SOCK_STREAM):
               ^^^^^^^^^^^^^^^^^^^^^^^^^^^^^^^^^^^^^^^
  File "/Library/Frameworks/Python.framework/Versions/3.12/lib/python3.12/socket.py", line 963, in getaddrinfo
    for res in _socket.getaddrinfo(host, port, family, type, proto, flags):
               ^^^^^^^^^^^^^^^^^^^^^^^^^^^^^^^^^^^^^^^^^^^^^^^^^^^^^^^^^^^
socket.gaierror: [Errno 8] nodename nor servname provided, or not known

During handling of the above exception, another exception occurred:

Traceback (most recent call last):
  File "/Users/ulisesv/Desktop/chewbacca/backend/api/src/database/db_mysql.py", line 9, in get_connection
    return pymysql.connect(
           ^^^^^^^^^^^^^^^^
  File "/Library/Frameworks/Python.framework/Versions/3.12/lib/python3.12/site-packages/pymysql/connections.py", line 358, in __init__
    self.connect()
  File "/Library/Frameworks/Python.framework/Versions/3.12/lib/python3.12/site-packages/pymysql/connections.py", line 711, in connect
    raise exc
pymysql.err.OperationalError: (2003, "Can't connect to MySQL server on 'mysql' ([Errno 8] nodename nor servname provided, or not known)")

2024-05-10 08:53:12 | ERROR | 'NoneType' object has no attribute 'cursor'
2024-05-10 08:53:12 | ERROR | Traceback (most recent call last):
  File "/Users/ulisesv/Desktop/chewbacca/backend/api/src/services/people.py", line 14, in get_people
    results = get_people_pagination(page)
              ^^^^^^^^^^^^^^^^^^^^^^^^^^^
  File "/Users/ulisesv/Desktop/chewbacca/backend/api/src/controllers/people.py", line 28, in get_people_pagination
    with conexion.cursor() as cursor:
         ^^^^^^^^^^^^^^^
AttributeError: 'NoneType' object has no attribute 'cursor'

2024-05-10 08:53:37 | ERROR | (2003, "Can't connect to MySQL server on 'mysql' ([Errno 8] nodename nor servname provided, or not known)")
2024-05-10 08:53:37 | ERROR | Traceback (most recent call last):
  File "/Library/Frameworks/Python.framework/Versions/3.12/lib/python3.12/site-packages/pymysql/connections.py", line 644, in connect
    sock = socket.create_connection(
           ^^^^^^^^^^^^^^^^^^^^^^^^^
  File "/Library/Frameworks/Python.framework/Versions/3.12/lib/python3.12/socket.py", line 828, in create_connection
    for res in getaddrinfo(host, port, 0, SOCK_STREAM):
               ^^^^^^^^^^^^^^^^^^^^^^^^^^^^^^^^^^^^^^^
  File "/Library/Frameworks/Python.framework/Versions/3.12/lib/python3.12/socket.py", line 963, in getaddrinfo
    for res in _socket.getaddrinfo(host, port, family, type, proto, flags):
               ^^^^^^^^^^^^^^^^^^^^^^^^^^^^^^^^^^^^^^^^^^^^^^^^^^^^^^^^^^^
socket.gaierror: [Errno 8] nodename nor servname provided, or not known

During handling of the above exception, another exception occurred:

Traceback (most recent call last):
  File "/Users/ulisesv/Desktop/chewbacca/backend/api/src/database/db_mysql.py", line 9, in get_connection
    return pymysql.connect(
           ^^^^^^^^^^^^^^^^
  File "/Library/Frameworks/Python.framework/Versions/3.12/lib/python3.12/site-packages/pymysql/connections.py", line 358, in __init__
    self.connect()
  File "/Library/Frameworks/Python.framework/Versions/3.12/lib/python3.12/site-packages/pymysql/connections.py", line 711, in connect
    raise exc
pymysql.err.OperationalError: (2003, "Can't connect to MySQL server on 'mysql' ([Errno 8] nodename nor servname provided, or not known)")

2024-05-10 08:53:37 | ERROR | 'NoneType' object has no attribute 'cursor'
2024-05-10 08:53:37 | ERROR | Traceback (most recent call last):
  File "/Users/ulisesv/Desktop/chewbacca/backend/api/src/services/people.py", line 14, in get_people
    results = get_people_pagination(page)
              ^^^^^^^^^^^^^^^^^^^^^^^^^^^
  File "/Users/ulisesv/Desktop/chewbacca/backend/api/src/controllers/people.py", line 28, in get_people_pagination
    with conexion.cursor() as cursor:
         ^^^^^^^^^^^^^^^
AttributeError: 'NoneType' object has no attribute 'cursor'

2024-05-10 08:54:05 | ERROR | (2003, "Can't connect to MySQL server on 'mysql' ([Errno 8] nodename nor servname provided, or not known)")
2024-05-10 08:54:05 | ERROR | Traceback (most recent call last):
  File "/Library/Frameworks/Python.framework/Versions/3.12/lib/python3.12/site-packages/pymysql/connections.py", line 644, in connect
    sock = socket.create_connection(
           ^^^^^^^^^^^^^^^^^^^^^^^^^
  File "/Library/Frameworks/Python.framework/Versions/3.12/lib/python3.12/socket.py", line 828, in create_connection
    for res in getaddrinfo(host, port, 0, SOCK_STREAM):
               ^^^^^^^^^^^^^^^^^^^^^^^^^^^^^^^^^^^^^^^
  File "/Library/Frameworks/Python.framework/Versions/3.12/lib/python3.12/socket.py", line 963, in getaddrinfo
    for res in _socket.getaddrinfo(host, port, family, type, proto, flags):
               ^^^^^^^^^^^^^^^^^^^^^^^^^^^^^^^^^^^^^^^^^^^^^^^^^^^^^^^^^^^
socket.gaierror: [Errno 8] nodename nor servname provided, or not known

During handling of the above exception, another exception occurred:

Traceback (most recent call last):
  File "/Users/ulisesv/Desktop/chewbacca/backend/api/src/database/db_mysql.py", line 9, in get_connection
    return pymysql.connect(
           ^^^^^^^^^^^^^^^^
  File "/Library/Frameworks/Python.framework/Versions/3.12/lib/python3.12/site-packages/pymysql/connections.py", line 358, in __init__
    self.connect()
  File "/Library/Frameworks/Python.framework/Versions/3.12/lib/python3.12/site-packages/pymysql/connections.py", line 711, in connect
    raise exc
pymysql.err.OperationalError: (2003, "Can't connect to MySQL server on 'mysql' ([Errno 8] nodename nor servname provided, or not known)")

2024-05-10 08:54:05 | ERROR | 'NoneType' object has no attribute 'cursor'
2024-05-10 08:54:05 | ERROR | Traceback (most recent call last):
  File "/Users/ulisesv/Desktop/chewbacca/backend/api/src/services/people.py", line 14, in get_people
    results = get_people_pagination(page)
              ^^^^^^^^^^^^^^^^^^^^^^^^^^^
  File "/Users/ulisesv/Desktop/chewbacca/backend/api/src/controllers/people.py", line 28, in get_people_pagination
    with conexion.cursor() as cursor:
         ^^^^^^^^^^^^^^^
AttributeError: 'NoneType' object has no attribute 'cursor'

2024-05-10 08:54:39 | ERROR | (2003, "Can't connect to MySQL server on 'mysql' ([Errno 8] nodename nor servname provided, or not known)")
2024-05-10 08:54:39 | ERROR | Traceback (most recent call last):
  File "/Library/Frameworks/Python.framework/Versions/3.12/lib/python3.12/site-packages/pymysql/connections.py", line 644, in connect
    sock = socket.create_connection(
           ^^^^^^^^^^^^^^^^^^^^^^^^^
  File "/Library/Frameworks/Python.framework/Versions/3.12/lib/python3.12/socket.py", line 828, in create_connection
    for res in getaddrinfo(host, port, 0, SOCK_STREAM):
               ^^^^^^^^^^^^^^^^^^^^^^^^^^^^^^^^^^^^^^^
  File "/Library/Frameworks/Python.framework/Versions/3.12/lib/python3.12/socket.py", line 963, in getaddrinfo
    for res in _socket.getaddrinfo(host, port, family, type, proto, flags):
               ^^^^^^^^^^^^^^^^^^^^^^^^^^^^^^^^^^^^^^^^^^^^^^^^^^^^^^^^^^^
socket.gaierror: [Errno 8] nodename nor servname provided, or not known

During handling of the above exception, another exception occurred:

Traceback (most recent call last):
  File "/Users/ulisesv/Desktop/chewbacca/backend/api/src/database/db_mysql.py", line 9, in get_connection
    return pymysql.connect(
           ^^^^^^^^^^^^^^^^
  File "/Library/Frameworks/Python.framework/Versions/3.12/lib/python3.12/site-packages/pymysql/connections.py", line 358, in __init__
    self.connect()
  File "/Library/Frameworks/Python.framework/Versions/3.12/lib/python3.12/site-packages/pymysql/connections.py", line 711, in connect
    raise exc
pymysql.err.OperationalError: (2003, "Can't connect to MySQL server on 'mysql' ([Errno 8] nodename nor servname provided, or not known)")

2024-05-10 08:54:39 | ERROR | 'NoneType' object has no attribute 'cursor'
2024-05-10 08:54:39 | ERROR | Traceback (most recent call last):
  File "/Users/ulisesv/Desktop/chewbacca/backend/api/src/services/people.py", line 14, in get_people
    results = get_people_pagination(page)
              ^^^^^^^^^^^^^^^^^^^^^^^^^^^
  File "/Users/ulisesv/Desktop/chewbacca/backend/api/src/controllers/people.py", line 29, in get_people_pagination
    with conexion.cursor() as cursor:
         ^^^^^^^^^^^^^^^
AttributeError: 'NoneType' object has no attribute 'cursor'

2024-05-10 08:54:55 | ERROR | (2003, "Can't connect to MySQL server on 'mysql' ([Errno 8] nodename nor servname provided, or not known)")
2024-05-10 08:54:55 | ERROR | Traceback (most recent call last):
  File "/Library/Frameworks/Python.framework/Versions/3.12/lib/python3.12/site-packages/pymysql/connections.py", line 644, in connect
    sock = socket.create_connection(
           ^^^^^^^^^^^^^^^^^^^^^^^^^
  File "/Library/Frameworks/Python.framework/Versions/3.12/lib/python3.12/socket.py", line 828, in create_connection
    for res in getaddrinfo(host, port, 0, SOCK_STREAM):
               ^^^^^^^^^^^^^^^^^^^^^^^^^^^^^^^^^^^^^^^
  File "/Library/Frameworks/Python.framework/Versions/3.12/lib/python3.12/socket.py", line 963, in getaddrinfo
    for res in _socket.getaddrinfo(host, port, family, type, proto, flags):
               ^^^^^^^^^^^^^^^^^^^^^^^^^^^^^^^^^^^^^^^^^^^^^^^^^^^^^^^^^^^
socket.gaierror: [Errno 8] nodename nor servname provided, or not known

During handling of the above exception, another exception occurred:

Traceback (most recent call last):
  File "/Users/ulisesv/Desktop/chewbacca/backend/api/src/database/db_mysql.py", line 9, in get_connection
    return pymysql.connect(
           ^^^^^^^^^^^^^^^^
  File "/Library/Frameworks/Python.framework/Versions/3.12/lib/python3.12/site-packages/pymysql/connections.py", line 358, in __init__
    self.connect()
  File "/Library/Frameworks/Python.framework/Versions/3.12/lib/python3.12/site-packages/pymysql/connections.py", line 711, in connect
    raise exc
pymysql.err.OperationalError: (2003, "Can't connect to MySQL server on 'mysql' ([Errno 8] nodename nor servname provided, or not known)")

2024-05-10 08:54:55 | ERROR | 'NoneType' object has no attribute 'cursor'
2024-05-10 08:54:55 | ERROR | Traceback (most recent call last):
  File "/Users/ulisesv/Desktop/chewbacca/backend/api/src/services/people.py", line 14, in get_people
    results = get_people_pagination(page)
              ^^^^^^^^^^^^^^^^^^^^^^^^^^^
  File "/Users/ulisesv/Desktop/chewbacca/backend/api/src/controllers/people.py", line 29, in get_people_pagination
    with conexion.cursor() as cursor:
         ^^^^^^^^^^^^^^^
AttributeError: 'NoneType' object has no attribute 'cursor'

2024-05-10 08:55:27 | ERROR | (2003, "Can't connect to MySQL server on 'mysql' ([Errno 8] nodename nor servname provided, or not known)")
2024-05-10 08:55:27 | ERROR | Traceback (most recent call last):
  File "/Library/Frameworks/Python.framework/Versions/3.12/lib/python3.12/site-packages/pymysql/connections.py", line 644, in connect
    sock = socket.create_connection(
           ^^^^^^^^^^^^^^^^^^^^^^^^^
  File "/Library/Frameworks/Python.framework/Versions/3.12/lib/python3.12/socket.py", line 828, in create_connection
    for res in getaddrinfo(host, port, 0, SOCK_STREAM):
               ^^^^^^^^^^^^^^^^^^^^^^^^^^^^^^^^^^^^^^^
  File "/Library/Frameworks/Python.framework/Versions/3.12/lib/python3.12/socket.py", line 963, in getaddrinfo
    for res in _socket.getaddrinfo(host, port, family, type, proto, flags):
               ^^^^^^^^^^^^^^^^^^^^^^^^^^^^^^^^^^^^^^^^^^^^^^^^^^^^^^^^^^^
socket.gaierror: [Errno 8] nodename nor servname provided, or not known

During handling of the above exception, another exception occurred:

Traceback (most recent call last):
  File "/Users/ulisesv/Desktop/chewbacca/backend/api/src/database/db_mysql.py", line 9, in get_connection
    return pymysql.connect(
           ^^^^^^^^^^^^^^^^
  File "/Library/Frameworks/Python.framework/Versions/3.12/lib/python3.12/site-packages/pymysql/connections.py", line 358, in __init__
    self.connect()
  File "/Library/Frameworks/Python.framework/Versions/3.12/lib/python3.12/site-packages/pymysql/connections.py", line 711, in connect
    raise exc
pymysql.err.OperationalError: (2003, "Can't connect to MySQL server on 'mysql' ([Errno 8] nodename nor servname provided, or not known)")

2024-05-10 08:55:27 | ERROR | 'NoneType' object has no attribute 'cursor'
2024-05-10 08:55:27 | ERROR | Traceback (most recent call last):
  File "/Users/ulisesv/Desktop/chewbacca/backend/api/src/services/people.py", line 14, in get_people
    results = get_people_pagination(page)
              ^^^^^^^^^^^^^^^^^^^^^^^^^^^
  File "/Users/ulisesv/Desktop/chewbacca/backend/api/src/controllers/people.py", line 29, in get_people_pagination
    with conexion.cursor() as cursor:
         ^^^^^^^^^^^^^^^
AttributeError: 'NoneType' object has no attribute 'cursor'

2024-05-10 08:55:51 | ERROR | (2003, "Can't connect to MySQL server on 'mysql' ([Errno 8] nodename nor servname provided, or not known)")
2024-05-10 08:55:51 | ERROR | Traceback (most recent call last):
  File "/Library/Frameworks/Python.framework/Versions/3.12/lib/python3.12/site-packages/pymysql/connections.py", line 644, in connect
    sock = socket.create_connection(
           ^^^^^^^^^^^^^^^^^^^^^^^^^
  File "/Library/Frameworks/Python.framework/Versions/3.12/lib/python3.12/socket.py", line 828, in create_connection
    for res in getaddrinfo(host, port, 0, SOCK_STREAM):
               ^^^^^^^^^^^^^^^^^^^^^^^^^^^^^^^^^^^^^^^
  File "/Library/Frameworks/Python.framework/Versions/3.12/lib/python3.12/socket.py", line 963, in getaddrinfo
    for res in _socket.getaddrinfo(host, port, family, type, proto, flags):
               ^^^^^^^^^^^^^^^^^^^^^^^^^^^^^^^^^^^^^^^^^^^^^^^^^^^^^^^^^^^
socket.gaierror: [Errno 8] nodename nor servname provided, or not known

During handling of the above exception, another exception occurred:

Traceback (most recent call last):
  File "/Users/ulisesv/Desktop/chewbacca/backend/api/src/database/db_mysql.py", line 9, in get_connection
    return pymysql.connect(
           ^^^^^^^^^^^^^^^^
  File "/Library/Frameworks/Python.framework/Versions/3.12/lib/python3.12/site-packages/pymysql/connections.py", line 358, in __init__
    self.connect()
  File "/Library/Frameworks/Python.framework/Versions/3.12/lib/python3.12/site-packages/pymysql/connections.py", line 711, in connect
    raise exc
pymysql.err.OperationalError: (2003, "Can't connect to MySQL server on 'mysql' ([Errno 8] nodename nor servname provided, or not known)")

2024-05-10 08:55:51 | ERROR | 'NoneType' object has no attribute 'cursor'
2024-05-10 08:55:51 | ERROR | Traceback (most recent call last):
  File "/Users/ulisesv/Desktop/chewbacca/backend/api/src/services/people.py", line 14, in get_people
    results = get_people_pagination(page)
              ^^^^^^^^^^^^^^^^^^^^^^^^^^^
  File "/Users/ulisesv/Desktop/chewbacca/backend/api/src/controllers/people.py", line 29, in get_people_pagination
    with conexion.cursor() as cursor:
         ^^^^^^^^^^^^^^^
AttributeError: 'NoneType' object has no attribute 'cursor'

2024-05-10 08:56:56 | ERROR | (2003, "Can't connect to MySQL server on 'mysql' ([Errno 8] nodename nor servname provided, or not known)")
2024-05-10 08:56:56 | ERROR | Traceback (most recent call last):
  File "/Library/Frameworks/Python.framework/Versions/3.12/lib/python3.12/site-packages/pymysql/connections.py", line 644, in connect
    sock = socket.create_connection(
           ^^^^^^^^^^^^^^^^^^^^^^^^^
  File "/Library/Frameworks/Python.framework/Versions/3.12/lib/python3.12/socket.py", line 828, in create_connection
    for res in getaddrinfo(host, port, 0, SOCK_STREAM):
               ^^^^^^^^^^^^^^^^^^^^^^^^^^^^^^^^^^^^^^^
  File "/Library/Frameworks/Python.framework/Versions/3.12/lib/python3.12/socket.py", line 963, in getaddrinfo
    for res in _socket.getaddrinfo(host, port, family, type, proto, flags):
               ^^^^^^^^^^^^^^^^^^^^^^^^^^^^^^^^^^^^^^^^^^^^^^^^^^^^^^^^^^^
socket.gaierror: [Errno 8] nodename nor servname provided, or not known

During handling of the above exception, another exception occurred:

Traceback (most recent call last):
  File "/Users/ulisesv/Desktop/chewbacca/backend/api/src/database/db_mysql.py", line 9, in get_connection
    return pymysql.connect(
           ^^^^^^^^^^^^^^^^
  File "/Library/Frameworks/Python.framework/Versions/3.12/lib/python3.12/site-packages/pymysql/connections.py", line 358, in __init__
    self.connect()
  File "/Library/Frameworks/Python.framework/Versions/3.12/lib/python3.12/site-packages/pymysql/connections.py", line 711, in connect
    raise exc
pymysql.err.OperationalError: (2003, "Can't connect to MySQL server on 'mysql' ([Errno 8] nodename nor servname provided, or not known)")

2024-05-10 08:56:56 | ERROR | 'NoneType' object has no attribute 'cursor'
2024-05-10 08:56:56 | ERROR | Traceback (most recent call last):
  File "/Users/ulisesv/Desktop/chewbacca/backend/api/src/services/people.py", line 14, in get_people
    results = get_people_pagination(page)
              ^^^^^^^^^^^^^^^^^^^^^^^^^^^
  File "/Users/ulisesv/Desktop/chewbacca/backend/api/src/controllers/people.py", line 29, in get_people_pagination
    with conexion.cursor() as cursor:
         ^^^^^^^^^^^^^^^
AttributeError: 'NoneType' object has no attribute 'cursor'

2024-05-10 08:56:59 | ERROR | (2003, "Can't connect to MySQL server on 'mysql' ([Errno 8] nodename nor servname provided, or not known)")
2024-05-10 08:56:59 | ERROR | Traceback (most recent call last):
  File "/Library/Frameworks/Python.framework/Versions/3.12/lib/python3.12/site-packages/pymysql/connections.py", line 644, in connect
    sock = socket.create_connection(
           ^^^^^^^^^^^^^^^^^^^^^^^^^
  File "/Library/Frameworks/Python.framework/Versions/3.12/lib/python3.12/socket.py", line 828, in create_connection
    for res in getaddrinfo(host, port, 0, SOCK_STREAM):
               ^^^^^^^^^^^^^^^^^^^^^^^^^^^^^^^^^^^^^^^
  File "/Library/Frameworks/Python.framework/Versions/3.12/lib/python3.12/socket.py", line 963, in getaddrinfo
    for res in _socket.getaddrinfo(host, port, family, type, proto, flags):
               ^^^^^^^^^^^^^^^^^^^^^^^^^^^^^^^^^^^^^^^^^^^^^^^^^^^^^^^^^^^
socket.gaierror: [Errno 8] nodename nor servname provided, or not known

During handling of the above exception, another exception occurred:

Traceback (most recent call last):
  File "/Users/ulisesv/Desktop/chewbacca/backend/api/src/database/db_mysql.py", line 9, in get_connection
    return pymysql.connect(
           ^^^^^^^^^^^^^^^^
  File "/Library/Frameworks/Python.framework/Versions/3.12/lib/python3.12/site-packages/pymysql/connections.py", line 358, in __init__
    self.connect()
  File "/Library/Frameworks/Python.framework/Versions/3.12/lib/python3.12/site-packages/pymysql/connections.py", line 711, in connect
    raise exc
pymysql.err.OperationalError: (2003, "Can't connect to MySQL server on 'mysql' ([Errno 8] nodename nor servname provided, or not known)")

2024-05-10 08:56:59 | ERROR | 'NoneType' object has no attribute 'cursor'
2024-05-10 08:56:59 | ERROR | Traceback (most recent call last):
  File "/Users/ulisesv/Desktop/chewbacca/backend/api/src/services/people.py", line 14, in get_people
    results = get_people_pagination(page)
              ^^^^^^^^^^^^^^^^^^^^^^^^^^^
  File "/Users/ulisesv/Desktop/chewbacca/backend/api/src/controllers/people.py", line 29, in get_people_pagination
    with conexion.cursor() as cursor:
         ^^^^^^^^^^^^^^^
AttributeError: 'NoneType' object has no attribute 'cursor'

2024-05-10 08:57:12 | ERROR | (2003, "Can't connect to MySQL server on 'mysql' ([Errno 8] nodename nor servname provided, or not known)")
2024-05-10 08:57:12 | ERROR | Traceback (most recent call last):
  File "/Library/Frameworks/Python.framework/Versions/3.12/lib/python3.12/site-packages/pymysql/connections.py", line 644, in connect
    sock = socket.create_connection(
           ^^^^^^^^^^^^^^^^^^^^^^^^^
  File "/Library/Frameworks/Python.framework/Versions/3.12/lib/python3.12/socket.py", line 828, in create_connection
    for res in getaddrinfo(host, port, 0, SOCK_STREAM):
               ^^^^^^^^^^^^^^^^^^^^^^^^^^^^^^^^^^^^^^^
  File "/Library/Frameworks/Python.framework/Versions/3.12/lib/python3.12/socket.py", line 963, in getaddrinfo
    for res in _socket.getaddrinfo(host, port, family, type, proto, flags):
               ^^^^^^^^^^^^^^^^^^^^^^^^^^^^^^^^^^^^^^^^^^^^^^^^^^^^^^^^^^^
socket.gaierror: [Errno 8] nodename nor servname provided, or not known

During handling of the above exception, another exception occurred:

Traceback (most recent call last):
  File "/Users/ulisesv/Desktop/chewbacca/backend/api/src/database/db_mysql.py", line 9, in get_connection
    return pymysql.connect(
           ^^^^^^^^^^^^^^^^
  File "/Library/Frameworks/Python.framework/Versions/3.12/lib/python3.12/site-packages/pymysql/connections.py", line 358, in __init__
    self.connect()
  File "/Library/Frameworks/Python.framework/Versions/3.12/lib/python3.12/site-packages/pymysql/connections.py", line 711, in connect
    raise exc
pymysql.err.OperationalError: (2003, "Can't connect to MySQL server on 'mysql' ([Errno 8] nodename nor servname provided, or not known)")

2024-05-10 08:57:12 | ERROR | 'NoneType' object has no attribute 'cursor'
2024-05-10 08:57:12 | ERROR | Traceback (most recent call last):
  File "/Users/ulisesv/Desktop/chewbacca/backend/api/src/services/people.py", line 14, in get_people
    results = get_people_pagination(page)
              ^^^^^^^^^^^^^^^^^^^^^^^^^^^
  File "/Users/ulisesv/Desktop/chewbacca/backend/api/src/controllers/people.py", line 29, in get_people_pagination
    with conexion.cursor() as cursor:
         ^^^^^^^^^^^^^^^
AttributeError: 'NoneType' object has no attribute 'cursor'

2024-05-10 08:57:14 | ERROR | (2003, "Can't connect to MySQL server on 'mysql' ([Errno 8] nodename nor servname provided, or not known)")
2024-05-10 08:57:14 | ERROR | Traceback (most recent call last):
  File "/Library/Frameworks/Python.framework/Versions/3.12/lib/python3.12/site-packages/pymysql/connections.py", line 644, in connect
    sock = socket.create_connection(
           ^^^^^^^^^^^^^^^^^^^^^^^^^
  File "/Library/Frameworks/Python.framework/Versions/3.12/lib/python3.12/socket.py", line 828, in create_connection
    for res in getaddrinfo(host, port, 0, SOCK_STREAM):
               ^^^^^^^^^^^^^^^^^^^^^^^^^^^^^^^^^^^^^^^
  File "/Library/Frameworks/Python.framework/Versions/3.12/lib/python3.12/socket.py", line 963, in getaddrinfo
    for res in _socket.getaddrinfo(host, port, family, type, proto, flags):
               ^^^^^^^^^^^^^^^^^^^^^^^^^^^^^^^^^^^^^^^^^^^^^^^^^^^^^^^^^^^
socket.gaierror: [Errno 8] nodename nor servname provided, or not known

During handling of the above exception, another exception occurred:

Traceback (most recent call last):
  File "/Users/ulisesv/Desktop/chewbacca/backend/api/src/database/db_mysql.py", line 9, in get_connection
    return pymysql.connect(
           ^^^^^^^^^^^^^^^^
  File "/Library/Frameworks/Python.framework/Versions/3.12/lib/python3.12/site-packages/pymysql/connections.py", line 358, in __init__
    self.connect()
  File "/Library/Frameworks/Python.framework/Versions/3.12/lib/python3.12/site-packages/pymysql/connections.py", line 711, in connect
    raise exc
pymysql.err.OperationalError: (2003, "Can't connect to MySQL server on 'mysql' ([Errno 8] nodename nor servname provided, or not known)")

2024-05-10 08:57:14 | ERROR | 'NoneType' object has no attribute 'cursor'
2024-05-10 08:57:14 | ERROR | Traceback (most recent call last):
  File "/Users/ulisesv/Desktop/chewbacca/backend/api/src/services/people.py", line 14, in get_people
    results = get_people_pagination(page)
              ^^^^^^^^^^^^^^^^^^^^^^^^^^^
  File "/Users/ulisesv/Desktop/chewbacca/backend/api/src/controllers/people.py", line 29, in get_people_pagination
    with conexion.cursor() as cursor:
         ^^^^^^^^^^^^^^^
AttributeError: 'NoneType' object has no attribute 'cursor'

2024-05-10 08:58:20 | ERROR | (2003, "Can't connect to MySQL server on 'mysql' ([Errno 8] nodename nor servname provided, or not known)")
2024-05-10 08:58:20 | ERROR | Traceback (most recent call last):
  File "/Library/Frameworks/Python.framework/Versions/3.12/lib/python3.12/site-packages/pymysql/connections.py", line 644, in connect
    sock = socket.create_connection(
           ^^^^^^^^^^^^^^^^^^^^^^^^^
  File "/Library/Frameworks/Python.framework/Versions/3.12/lib/python3.12/socket.py", line 828, in create_connection
    for res in getaddrinfo(host, port, 0, SOCK_STREAM):
               ^^^^^^^^^^^^^^^^^^^^^^^^^^^^^^^^^^^^^^^
  File "/Library/Frameworks/Python.framework/Versions/3.12/lib/python3.12/socket.py", line 963, in getaddrinfo
    for res in _socket.getaddrinfo(host, port, family, type, proto, flags):
               ^^^^^^^^^^^^^^^^^^^^^^^^^^^^^^^^^^^^^^^^^^^^^^^^^^^^^^^^^^^
socket.gaierror: [Errno 8] nodename nor servname provided, or not known

During handling of the above exception, another exception occurred:

Traceback (most recent call last):
  File "/Users/ulisesv/Desktop/chewbacca/backend/api/src/database/db_mysql.py", line 9, in get_connection
    return pymysql.connect(
           ^^^^^^^^^^^^^^^^
  File "/Library/Frameworks/Python.framework/Versions/3.12/lib/python3.12/site-packages/pymysql/connections.py", line 358, in __init__
    self.connect()
  File "/Library/Frameworks/Python.framework/Versions/3.12/lib/python3.12/site-packages/pymysql/connections.py", line 711, in connect
    raise exc
pymysql.err.OperationalError: (2003, "Can't connect to MySQL server on 'mysql' ([Errno 8] nodename nor servname provided, or not known)")

2024-05-10 08:58:20 | ERROR | 'NoneType' object has no attribute 'cursor'
2024-05-10 08:58:20 | ERROR | Traceback (most recent call last):
  File "/Users/ulisesv/Desktop/chewbacca/backend/api/src/services/people.py", line 14, in get_people
    results = get_people_pagination(page)
              ^^^^^^^^^^^^^^^^^^^^^^^^^^^
  File "/Users/ulisesv/Desktop/chewbacca/backend/api/src/controllers/people.py", line 30, in get_people_pagination
    with conexion.cursor() as cursor:
         ^^^^^^^^^^^^^^^
AttributeError: 'NoneType' object has no attribute 'cursor'

2024-05-10 08:58:22 | ERROR | (2003, "Can't connect to MySQL server on 'mysql' ([Errno 8] nodename nor servname provided, or not known)")
2024-05-10 08:58:22 | ERROR | Traceback (most recent call last):
  File "/Library/Frameworks/Python.framework/Versions/3.12/lib/python3.12/site-packages/pymysql/connections.py", line 644, in connect
    sock = socket.create_connection(
           ^^^^^^^^^^^^^^^^^^^^^^^^^
  File "/Library/Frameworks/Python.framework/Versions/3.12/lib/python3.12/socket.py", line 828, in create_connection
    for res in getaddrinfo(host, port, 0, SOCK_STREAM):
               ^^^^^^^^^^^^^^^^^^^^^^^^^^^^^^^^^^^^^^^
  File "/Library/Frameworks/Python.framework/Versions/3.12/lib/python3.12/socket.py", line 963, in getaddrinfo
    for res in _socket.getaddrinfo(host, port, family, type, proto, flags):
               ^^^^^^^^^^^^^^^^^^^^^^^^^^^^^^^^^^^^^^^^^^^^^^^^^^^^^^^^^^^
socket.gaierror: [Errno 8] nodename nor servname provided, or not known

During handling of the above exception, another exception occurred:

Traceback (most recent call last):
  File "/Users/ulisesv/Desktop/chewbacca/backend/api/src/database/db_mysql.py", line 9, in get_connection
    return pymysql.connect(
           ^^^^^^^^^^^^^^^^
  File "/Library/Frameworks/Python.framework/Versions/3.12/lib/python3.12/site-packages/pymysql/connections.py", line 358, in __init__
    self.connect()
  File "/Library/Frameworks/Python.framework/Versions/3.12/lib/python3.12/site-packages/pymysql/connections.py", line 711, in connect
    raise exc
pymysql.err.OperationalError: (2003, "Can't connect to MySQL server on 'mysql' ([Errno 8] nodename nor servname provided, or not known)")

2024-05-10 08:58:22 | ERROR | 'NoneType' object has no attribute 'cursor'
2024-05-10 08:58:22 | ERROR | Traceback (most recent call last):
  File "/Users/ulisesv/Desktop/chewbacca/backend/api/src/services/people.py", line 14, in get_people
    results = get_people_pagination(page)
              ^^^^^^^^^^^^^^^^^^^^^^^^^^^
  File "/Users/ulisesv/Desktop/chewbacca/backend/api/src/controllers/people.py", line 30, in get_people_pagination
    with conexion.cursor() as cursor:
         ^^^^^^^^^^^^^^^
AttributeError: 'NoneType' object has no attribute 'cursor'

2024-05-10 09:00:37 | ERROR | (2003, "Can't connect to MySQL server on 'mysql' ([Errno 8] nodename nor servname provided, or not known)")
2024-05-10 09:00:37 | ERROR | Traceback (most recent call last):
  File "/Library/Frameworks/Python.framework/Versions/3.12/lib/python3.12/site-packages/pymysql/connections.py", line 644, in connect
    sock = socket.create_connection(
           ^^^^^^^^^^^^^^^^^^^^^^^^^
  File "/Library/Frameworks/Python.framework/Versions/3.12/lib/python3.12/socket.py", line 828, in create_connection
    for res in getaddrinfo(host, port, 0, SOCK_STREAM):
               ^^^^^^^^^^^^^^^^^^^^^^^^^^^^^^^^^^^^^^^
  File "/Library/Frameworks/Python.framework/Versions/3.12/lib/python3.12/socket.py", line 963, in getaddrinfo
    for res in _socket.getaddrinfo(host, port, family, type, proto, flags):
               ^^^^^^^^^^^^^^^^^^^^^^^^^^^^^^^^^^^^^^^^^^^^^^^^^^^^^^^^^^^
socket.gaierror: [Errno 8] nodename nor servname provided, or not known

During handling of the above exception, another exception occurred:

Traceback (most recent call last):
  File "/Users/ulisesv/Desktop/chewbacca/backend/api/src/database/db_mysql.py", line 9, in get_connection
    return pymysql.connect(
           ^^^^^^^^^^^^^^^^
  File "/Library/Frameworks/Python.framework/Versions/3.12/lib/python3.12/site-packages/pymysql/connections.py", line 358, in __init__
    self.connect()
  File "/Library/Frameworks/Python.framework/Versions/3.12/lib/python3.12/site-packages/pymysql/connections.py", line 711, in connect
    raise exc
pymysql.err.OperationalError: (2003, "Can't connect to MySQL server on 'mysql' ([Errno 8] nodename nor servname provided, or not known)")

2024-05-10 09:00:37 | ERROR | 'NoneType' object has no attribute 'cursor'
2024-05-10 09:00:37 | ERROR | Traceback (most recent call last):
  File "/Users/ulisesv/Desktop/chewbacca/backend/api/src/services/people.py", line 14, in get_people
    results = get_people_pagination(page)
              ^^^^^^^^^^^^^^^^^^^^^^^^^^^
  File "/Users/ulisesv/Desktop/chewbacca/backend/api/src/controllers/people.py", line 30, in get_people_pagination
    with conexion.cursor() as cursor:
         ^^^^^^^^^^^^^^^
AttributeError: 'NoneType' object has no attribute 'cursor'

2024-05-10 09:07:37 | ERROR | (2003, "Can't connect to MySQL server on 'mysql' ([Errno 8] nodename nor servname provided, or not known)")
2024-05-10 09:07:37 | ERROR | Traceback (most recent call last):
  File "/Library/Frameworks/Python.framework/Versions/3.12/lib/python3.12/site-packages/pymysql/connections.py", line 644, in connect
    sock = socket.create_connection(
           ^^^^^^^^^^^^^^^^^^^^^^^^^
  File "/Library/Frameworks/Python.framework/Versions/3.12/lib/python3.12/socket.py", line 828, in create_connection
    for res in getaddrinfo(host, port, 0, SOCK_STREAM):
               ^^^^^^^^^^^^^^^^^^^^^^^^^^^^^^^^^^^^^^^
  File "/Library/Frameworks/Python.framework/Versions/3.12/lib/python3.12/socket.py", line 963, in getaddrinfo
    for res in _socket.getaddrinfo(host, port, family, type, proto, flags):
               ^^^^^^^^^^^^^^^^^^^^^^^^^^^^^^^^^^^^^^^^^^^^^^^^^^^^^^^^^^^
socket.gaierror: [Errno 8] nodename nor servname provided, or not known

During handling of the above exception, another exception occurred:

Traceback (most recent call last):
  File "/Users/ulisesv/Desktop/chewbacca/backend/api/src/database/db_mysql.py", line 9, in get_connection
    return pymysql.connect(
           ^^^^^^^^^^^^^^^^
  File "/Library/Frameworks/Python.framework/Versions/3.12/lib/python3.12/site-packages/pymysql/connections.py", line 358, in __init__
    self.connect()
  File "/Library/Frameworks/Python.framework/Versions/3.12/lib/python3.12/site-packages/pymysql/connections.py", line 711, in connect
    raise exc
pymysql.err.OperationalError: (2003, "Can't connect to MySQL server on 'mysql' ([Errno 8] nodename nor servname provided, or not known)")

2024-05-10 09:07:37 | ERROR | 'NoneType' object has no attribute 'cursor'
2024-05-10 09:07:37 | ERROR | Traceback (most recent call last):
  File "/Users/ulisesv/Desktop/chewbacca/backend/api/src/services/people.py", line 14, in get_people
    results = get_people_pagination(page)
              ^^^^^^^^^^^^^^^^^^^^^^^^^^^
  File "/Users/ulisesv/Desktop/chewbacca/backend/api/src/controllers/people.py", line 30, in get_people_pagination
    with conexion.cursor() as cursor:
         ^^^^^^^^^^^^^^^
AttributeError: 'NoneType' object has no attribute 'cursor'

2024-05-10 09:10:16 | ERROR | mysql not found. Declare it as envvar or define a default value.
2024-05-10 09:10:16 | ERROR | Traceback (most recent call last):
  File "/Users/ulisesv/Desktop/chewbacca/backend/api/src/database/db_mysql.py", line 10, in get_connection
    host=config('mysql'),
         ^^^^^^^^^^^^^^^
  File "/Library/Frameworks/Python.framework/Versions/3.12/lib/python3.12/site-packages/decouple.py", line 248, in __call__
    return self.config(*args, **kwargs)
           ^^^^^^^^^^^^^^^^^^^^^^^^^^^^
  File "/Library/Frameworks/Python.framework/Versions/3.12/lib/python3.12/site-packages/decouple.py", line 107, in __call__
    return self.get(*args, **kwargs)
           ^^^^^^^^^^^^^^^^^^^^^^^^^
  File "/Library/Frameworks/Python.framework/Versions/3.12/lib/python3.12/site-packages/decouple.py", line 92, in get
    raise UndefinedValueError('{} not found. Declare it as envvar or define a default value.'.format(option))
decouple.UndefinedValueError: mysql not found. Declare it as envvar or define a default value.

2024-05-10 09:10:16 | ERROR | 'NoneType' object has no attribute 'cursor'
2024-05-10 09:10:16 | ERROR | Traceback (most recent call last):
  File "/Users/ulisesv/Desktop/chewbacca/backend/api/src/services/people.py", line 14, in get_people
    results = get_people_pagination(page)
              ^^^^^^^^^^^^^^^^^^^^^^^^^^^
  File "/Users/ulisesv/Desktop/chewbacca/backend/api/src/controllers/people.py", line 30, in get_people_pagination
    with conexion.cursor() as cursor:
         ^^^^^^^^^^^^^^^
AttributeError: 'NoneType' object has no attribute 'cursor'

2024-05-10 09:11:36 | ERROR | mysql not found. Declare it as envvar or define a default value.
2024-05-10 09:11:36 | ERROR | Traceback (most recent call last):
  File "/Users/ulisesv/Desktop/chewbacca/backend/api/src/database/db_mysql.py", line 10, in get_connection
    host=config('mysql'),
         ^^^^^^^^^^^^^^^
  File "/Library/Frameworks/Python.framework/Versions/3.12/lib/python3.12/site-packages/decouple.py", line 248, in __call__
    return self.config(*args, **kwargs)
           ^^^^^^^^^^^^^^^^^^^^^^^^^^^^
  File "/Library/Frameworks/Python.framework/Versions/3.12/lib/python3.12/site-packages/decouple.py", line 107, in __call__
    return self.get(*args, **kwargs)
           ^^^^^^^^^^^^^^^^^^^^^^^^^
  File "/Library/Frameworks/Python.framework/Versions/3.12/lib/python3.12/site-packages/decouple.py", line 92, in get
    raise UndefinedValueError('{} not found. Declare it as envvar or define a default value.'.format(option))
decouple.UndefinedValueError: mysql not found. Declare it as envvar or define a default value.

2024-05-10 09:11:36 | ERROR | 'NoneType' object has no attribute 'cursor'
2024-05-10 09:11:36 | ERROR | Traceback (most recent call last):
  File "/Users/ulisesv/Desktop/chewbacca/backend/api/src/services/people.py", line 14, in get_people
    results = get_people_pagination(page)
              ^^^^^^^^^^^^^^^^^^^^^^^^^^^
  File "/Users/ulisesv/Desktop/chewbacca/backend/api/src/controllers/people.py", line 30, in get_people_pagination
    with conexion.cursor() as cursor:
         ^^^^^^^^^^^^^^^
AttributeError: 'NoneType' object has no attribute 'cursor'

2024-05-10 09:12:02 | ERROR | (2003, "Can't connect to MySQL server on 'mysql' ([Errno 8] nodename nor servname provided, or not known)")
2024-05-10 09:12:02 | ERROR | Traceback (most recent call last):
  File "/Library/Frameworks/Python.framework/Versions/3.12/lib/python3.12/site-packages/pymysql/connections.py", line 644, in connect
    sock = socket.create_connection(
           ^^^^^^^^^^^^^^^^^^^^^^^^^
  File "/Library/Frameworks/Python.framework/Versions/3.12/lib/python3.12/socket.py", line 828, in create_connection
    for res in getaddrinfo(host, port, 0, SOCK_STREAM):
               ^^^^^^^^^^^^^^^^^^^^^^^^^^^^^^^^^^^^^^^
  File "/Library/Frameworks/Python.framework/Versions/3.12/lib/python3.12/socket.py", line 963, in getaddrinfo
    for res in _socket.getaddrinfo(host, port, family, type, proto, flags):
               ^^^^^^^^^^^^^^^^^^^^^^^^^^^^^^^^^^^^^^^^^^^^^^^^^^^^^^^^^^^
socket.gaierror: [Errno 8] nodename nor servname provided, or not known

During handling of the above exception, another exception occurred:

Traceback (most recent call last):
  File "/Users/ulisesv/Desktop/chewbacca/backend/api/src/database/db_mysql.py", line 9, in get_connection
    return pymysql.connect(
           ^^^^^^^^^^^^^^^^
  File "/Library/Frameworks/Python.framework/Versions/3.12/lib/python3.12/site-packages/pymysql/connections.py", line 358, in __init__
    self.connect()
  File "/Library/Frameworks/Python.framework/Versions/3.12/lib/python3.12/site-packages/pymysql/connections.py", line 711, in connect
    raise exc
pymysql.err.OperationalError: (2003, "Can't connect to MySQL server on 'mysql' ([Errno 8] nodename nor servname provided, or not known)")

2024-05-10 09:12:02 | ERROR | 'NoneType' object has no attribute 'cursor'
2024-05-10 09:12:02 | ERROR | Traceback (most recent call last):
  File "/Users/ulisesv/Desktop/chewbacca/backend/api/src/services/people.py", line 14, in get_people
    results = get_people_pagination(page)
              ^^^^^^^^^^^^^^^^^^^^^^^^^^^
  File "/Users/ulisesv/Desktop/chewbacca/backend/api/src/controllers/people.py", line 30, in get_people_pagination
    with conexion.cursor() as cursor:
         ^^^^^^^^^^^^^^^
AttributeError: 'NoneType' object has no attribute 'cursor'

2024-05-10 09:12:03 | ERROR | (2003, "Can't connect to MySQL server on 'mysql' ([Errno 8] nodename nor servname provided, or not known)")
2024-05-10 09:12:03 | ERROR | Traceback (most recent call last):
  File "/Library/Frameworks/Python.framework/Versions/3.12/lib/python3.12/site-packages/pymysql/connections.py", line 644, in connect
    sock = socket.create_connection(
           ^^^^^^^^^^^^^^^^^^^^^^^^^
  File "/Library/Frameworks/Python.framework/Versions/3.12/lib/python3.12/socket.py", line 828, in create_connection
    for res in getaddrinfo(host, port, 0, SOCK_STREAM):
               ^^^^^^^^^^^^^^^^^^^^^^^^^^^^^^^^^^^^^^^
  File "/Library/Frameworks/Python.framework/Versions/3.12/lib/python3.12/socket.py", line 963, in getaddrinfo
    for res in _socket.getaddrinfo(host, port, family, type, proto, flags):
               ^^^^^^^^^^^^^^^^^^^^^^^^^^^^^^^^^^^^^^^^^^^^^^^^^^^^^^^^^^^
socket.gaierror: [Errno 8] nodename nor servname provided, or not known

During handling of the above exception, another exception occurred:

Traceback (most recent call last):
  File "/Users/ulisesv/Desktop/chewbacca/backend/api/src/database/db_mysql.py", line 9, in get_connection
    return pymysql.connect(
           ^^^^^^^^^^^^^^^^
  File "/Library/Frameworks/Python.framework/Versions/3.12/lib/python3.12/site-packages/pymysql/connections.py", line 358, in __init__
    self.connect()
  File "/Library/Frameworks/Python.framework/Versions/3.12/lib/python3.12/site-packages/pymysql/connections.py", line 711, in connect
    raise exc
pymysql.err.OperationalError: (2003, "Can't connect to MySQL server on 'mysql' ([Errno 8] nodename nor servname provided, or not known)")

2024-05-10 09:12:03 | ERROR | 'NoneType' object has no attribute 'cursor'
2024-05-10 09:12:03 | ERROR | Traceback (most recent call last):
  File "/Users/ulisesv/Desktop/chewbacca/backend/api/src/services/people.py", line 14, in get_people
    results = get_people_pagination(page)
              ^^^^^^^^^^^^^^^^^^^^^^^^^^^
  File "/Users/ulisesv/Desktop/chewbacca/backend/api/src/controllers/people.py", line 30, in get_people_pagination
    with conexion.cursor() as cursor:
         ^^^^^^^^^^^^^^^
AttributeError: 'NoneType' object has no attribute 'cursor'

2024-05-10 09:13:38 | ERROR | (2003, "Can't connect to MySQL server on 'mysql' ([Errno 8] nodename nor servname provided, or not known)")
2024-05-10 09:13:38 | ERROR | Traceback (most recent call last):
  File "/Library/Frameworks/Python.framework/Versions/3.12/lib/python3.12/site-packages/pymysql/connections.py", line 644, in connect
    sock = socket.create_connection(
           ^^^^^^^^^^^^^^^^^^^^^^^^^
  File "/Library/Frameworks/Python.framework/Versions/3.12/lib/python3.12/socket.py", line 828, in create_connection
    for res in getaddrinfo(host, port, 0, SOCK_STREAM):
               ^^^^^^^^^^^^^^^^^^^^^^^^^^^^^^^^^^^^^^^
  File "/Library/Frameworks/Python.framework/Versions/3.12/lib/python3.12/socket.py", line 963, in getaddrinfo
    for res in _socket.getaddrinfo(host, port, family, type, proto, flags):
               ^^^^^^^^^^^^^^^^^^^^^^^^^^^^^^^^^^^^^^^^^^^^^^^^^^^^^^^^^^^
socket.gaierror: [Errno 8] nodename nor servname provided, or not known

During handling of the above exception, another exception occurred:

Traceback (most recent call last):
  File "/Users/ulisesv/Desktop/chewbacca/backend/api/src/database/db_mysql.py", line 9, in get_connection
    return pymysql.connect(
           ^^^^^^^^^^^^^^^^
  File "/Library/Frameworks/Python.framework/Versions/3.12/lib/python3.12/site-packages/pymysql/connections.py", line 358, in __init__
    self.connect()
  File "/Library/Frameworks/Python.framework/Versions/3.12/lib/python3.12/site-packages/pymysql/connections.py", line 711, in connect
    raise exc
pymysql.err.OperationalError: (2003, "Can't connect to MySQL server on 'mysql' ([Errno 8] nodename nor servname provided, or not known)")

2024-05-10 09:13:38 | ERROR | 'NoneType' object has no attribute 'cursor'
2024-05-10 09:13:38 | ERROR | Traceback (most recent call last):
  File "/Users/ulisesv/Desktop/chewbacca/backend/api/src/services/people.py", line 14, in get_people
    results = get_people_pagination(page)
              ^^^^^^^^^^^^^^^^^^^^^^^^^^^
  File "/Users/ulisesv/Desktop/chewbacca/backend/api/src/controllers/people.py", line 30, in get_people_pagination
    with conexion.cursor() as cursor:
         ^^^^^^^^^^^^^^^
AttributeError: 'NoneType' object has no attribute 'cursor'

2024-05-10 09:13:40 | ERROR | (2003, "Can't connect to MySQL server on 'mysql' ([Errno 8] nodename nor servname provided, or not known)")
2024-05-10 09:13:40 | ERROR | Traceback (most recent call last):
  File "/Library/Frameworks/Python.framework/Versions/3.12/lib/python3.12/site-packages/pymysql/connections.py", line 644, in connect
    sock = socket.create_connection(
           ^^^^^^^^^^^^^^^^^^^^^^^^^
  File "/Library/Frameworks/Python.framework/Versions/3.12/lib/python3.12/socket.py", line 828, in create_connection
    for res in getaddrinfo(host, port, 0, SOCK_STREAM):
               ^^^^^^^^^^^^^^^^^^^^^^^^^^^^^^^^^^^^^^^
  File "/Library/Frameworks/Python.framework/Versions/3.12/lib/python3.12/socket.py", line 963, in getaddrinfo
    for res in _socket.getaddrinfo(host, port, family, type, proto, flags):
               ^^^^^^^^^^^^^^^^^^^^^^^^^^^^^^^^^^^^^^^^^^^^^^^^^^^^^^^^^^^
socket.gaierror: [Errno 8] nodename nor servname provided, or not known

During handling of the above exception, another exception occurred:

Traceback (most recent call last):
  File "/Users/ulisesv/Desktop/chewbacca/backend/api/src/database/db_mysql.py", line 9, in get_connection
    return pymysql.connect(
           ^^^^^^^^^^^^^^^^
  File "/Library/Frameworks/Python.framework/Versions/3.12/lib/python3.12/site-packages/pymysql/connections.py", line 358, in __init__
    self.connect()
  File "/Library/Frameworks/Python.framework/Versions/3.12/lib/python3.12/site-packages/pymysql/connections.py", line 711, in connect
    raise exc
pymysql.err.OperationalError: (2003, "Can't connect to MySQL server on 'mysql' ([Errno 8] nodename nor servname provided, or not known)")

2024-05-10 09:13:40 | ERROR | 'NoneType' object has no attribute 'cursor'
2024-05-10 09:13:40 | ERROR | Traceback (most recent call last):
  File "/Users/ulisesv/Desktop/chewbacca/backend/api/src/services/people.py", line 14, in get_people
    results = get_people_pagination(page)
              ^^^^^^^^^^^^^^^^^^^^^^^^^^^
  File "/Users/ulisesv/Desktop/chewbacca/backend/api/src/controllers/people.py", line 30, in get_people_pagination
    with conexion.cursor() as cursor:
         ^^^^^^^^^^^^^^^
AttributeError: 'NoneType' object has no attribute 'cursor'

2024-05-10 09:14:57 | ERROR | (2003, "Can't connect to MySQL server on 'mysql' ([Errno 8] nodename nor servname provided, or not known)")
2024-05-10 09:14:57 | ERROR | Traceback (most recent call last):
  File "/Library/Frameworks/Python.framework/Versions/3.12/lib/python3.12/site-packages/pymysql/connections.py", line 644, in connect
    sock = socket.create_connection(
           ^^^^^^^^^^^^^^^^^^^^^^^^^
  File "/Library/Frameworks/Python.framework/Versions/3.12/lib/python3.12/socket.py", line 828, in create_connection
    for res in getaddrinfo(host, port, 0, SOCK_STREAM):
               ^^^^^^^^^^^^^^^^^^^^^^^^^^^^^^^^^^^^^^^
  File "/Library/Frameworks/Python.framework/Versions/3.12/lib/python3.12/socket.py", line 963, in getaddrinfo
    for res in _socket.getaddrinfo(host, port, family, type, proto, flags):
               ^^^^^^^^^^^^^^^^^^^^^^^^^^^^^^^^^^^^^^^^^^^^^^^^^^^^^^^^^^^
socket.gaierror: [Errno 8] nodename nor servname provided, or not known

During handling of the above exception, another exception occurred:

Traceback (most recent call last):
  File "/Users/ulisesv/Desktop/chewbacca/backend/api/src/database/db_mysql.py", line 9, in get_connection
    return pymysql.connect(
           ^^^^^^^^^^^^^^^^
  File "/Library/Frameworks/Python.framework/Versions/3.12/lib/python3.12/site-packages/pymysql/connections.py", line 358, in __init__
    self.connect()
  File "/Library/Frameworks/Python.framework/Versions/3.12/lib/python3.12/site-packages/pymysql/connections.py", line 711, in connect
    raise exc
pymysql.err.OperationalError: (2003, "Can't connect to MySQL server on 'mysql' ([Errno 8] nodename nor servname provided, or not known)")

2024-05-10 09:14:57 | ERROR | 'NoneType' object has no attribute 'cursor'
2024-05-10 09:14:57 | ERROR | Traceback (most recent call last):
  File "/Users/ulisesv/Desktop/chewbacca/backend/api/src/services/people.py", line 14, in get_people
    results = get_people_pagination(page)
              ^^^^^^^^^^^^^^^^^^^^^^^^^^^
  File "/Users/ulisesv/Desktop/chewbacca/backend/api/src/controllers/people.py", line 30, in get_people_pagination
    with conexion.cursor() as cursor:
         ^^^^^^^^^^^^^^^
AttributeError: 'NoneType' object has no attribute 'cursor'

2024-05-10 09:44:15 | ERROR | (2003, "Can't connect to MySQL server on 'mysql' ([Errno 8] nodename nor servname provided, or not known)")
2024-05-10 09:44:15 | ERROR | Traceback (most recent call last):
  File "/Library/Frameworks/Python.framework/Versions/3.12/lib/python3.12/site-packages/pymysql/connections.py", line 644, in connect
    sock = socket.create_connection(
           ^^^^^^^^^^^^^^^^^^^^^^^^^
  File "/Library/Frameworks/Python.framework/Versions/3.12/lib/python3.12/socket.py", line 828, in create_connection
    for res in getaddrinfo(host, port, 0, SOCK_STREAM):
               ^^^^^^^^^^^^^^^^^^^^^^^^^^^^^^^^^^^^^^^
  File "/Library/Frameworks/Python.framework/Versions/3.12/lib/python3.12/socket.py", line 963, in getaddrinfo
    for res in _socket.getaddrinfo(host, port, family, type, proto, flags):
               ^^^^^^^^^^^^^^^^^^^^^^^^^^^^^^^^^^^^^^^^^^^^^^^^^^^^^^^^^^^
socket.gaierror: [Errno 8] nodename nor servname provided, or not known

During handling of the above exception, another exception occurred:

Traceback (most recent call last):
  File "/Users/ulisesv/Desktop/chewbacca/backend/api/src/database/db_mysql.py", line 9, in get_connection
    return pymysql.connect(
           ^^^^^^^^^^^^^^^^
  File "/Library/Frameworks/Python.framework/Versions/3.12/lib/python3.12/site-packages/pymysql/connections.py", line 358, in __init__
    self.connect()
  File "/Library/Frameworks/Python.framework/Versions/3.12/lib/python3.12/site-packages/pymysql/connections.py", line 711, in connect
    raise exc
pymysql.err.OperationalError: (2003, "Can't connect to MySQL server on 'mysql' ([Errno 8] nodename nor servname provided, or not known)")

2024-05-10 09:44:15 | ERROR | 'NoneType' object has no attribute 'cursor'
2024-05-10 09:44:15 | ERROR | Traceback (most recent call last):
  File "/Users/ulisesv/Desktop/chewbacca/backend/api/src/services/people.py", line 14, in get_people
    results = get_people_pagination(page)
              ^^^^^^^^^^^^^^^^^^^^^^^^^^^
  File "/Users/ulisesv/Desktop/chewbacca/backend/api/src/controllers/people.py", line 30, in get_people_pagination
    with conexion.cursor() as cursor:
         ^^^^^^^^^^^^^^^
AttributeError: 'NoneType' object has no attribute 'cursor'

2024-05-10 09:44:40 | ERROR | (2003, "Can't connect to MySQL server on 'mysql' ([Errno 8] nodename nor servname provided, or not known)")
2024-05-10 09:44:40 | ERROR | Traceback (most recent call last):
  File "/Library/Frameworks/Python.framework/Versions/3.12/lib/python3.12/site-packages/pymysql/connections.py", line 644, in connect
    sock = socket.create_connection(
           ^^^^^^^^^^^^^^^^^^^^^^^^^
  File "/Library/Frameworks/Python.framework/Versions/3.12/lib/python3.12/socket.py", line 828, in create_connection
    for res in getaddrinfo(host, port, 0, SOCK_STREAM):
               ^^^^^^^^^^^^^^^^^^^^^^^^^^^^^^^^^^^^^^^
  File "/Library/Frameworks/Python.framework/Versions/3.12/lib/python3.12/socket.py", line 963, in getaddrinfo
    for res in _socket.getaddrinfo(host, port, family, type, proto, flags):
               ^^^^^^^^^^^^^^^^^^^^^^^^^^^^^^^^^^^^^^^^^^^^^^^^^^^^^^^^^^^
socket.gaierror: [Errno 8] nodename nor servname provided, or not known

During handling of the above exception, another exception occurred:

Traceback (most recent call last):
  File "/Users/ulisesv/Desktop/chewbacca/backend/api/src/database/db_mysql.py", line 9, in get_connection
    return pymysql.connect(
           ^^^^^^^^^^^^^^^^
  File "/Library/Frameworks/Python.framework/Versions/3.12/lib/python3.12/site-packages/pymysql/connections.py", line 358, in __init__
    self.connect()
  File "/Library/Frameworks/Python.framework/Versions/3.12/lib/python3.12/site-packages/pymysql/connections.py", line 711, in connect
    raise exc
pymysql.err.OperationalError: (2003, "Can't connect to MySQL server on 'mysql' ([Errno 8] nodename nor servname provided, or not known)")

2024-05-10 09:44:40 | ERROR | 'NoneType' object has no attribute 'cursor'
2024-05-10 09:44:40 | ERROR | Traceback (most recent call last):
  File "/Users/ulisesv/Desktop/chewbacca/backend/api/src/services/people.py", line 14, in get_people
    results = get_people_pagination(page)
              ^^^^^^^^^^^^^^^^^^^^^^^^^^^
  File "/Users/ulisesv/Desktop/chewbacca/backend/api/src/controllers/people.py", line 30, in get_people_pagination
    with conexion.cursor() as cursor:
         ^^^^^^^^^^^^^^^
AttributeError: 'NoneType' object has no attribute 'cursor'

2024-05-10 09:44:41 | ERROR | (2003, "Can't connect to MySQL server on 'mysql' ([Errno 8] nodename nor servname provided, or not known)")
2024-05-10 09:44:41 | ERROR | Traceback (most recent call last):
  File "/Library/Frameworks/Python.framework/Versions/3.12/lib/python3.12/site-packages/pymysql/connections.py", line 644, in connect
    sock = socket.create_connection(
           ^^^^^^^^^^^^^^^^^^^^^^^^^
  File "/Library/Frameworks/Python.framework/Versions/3.12/lib/python3.12/socket.py", line 828, in create_connection
    for res in getaddrinfo(host, port, 0, SOCK_STREAM):
               ^^^^^^^^^^^^^^^^^^^^^^^^^^^^^^^^^^^^^^^
  File "/Library/Frameworks/Python.framework/Versions/3.12/lib/python3.12/socket.py", line 963, in getaddrinfo
    for res in _socket.getaddrinfo(host, port, family, type, proto, flags):
               ^^^^^^^^^^^^^^^^^^^^^^^^^^^^^^^^^^^^^^^^^^^^^^^^^^^^^^^^^^^
socket.gaierror: [Errno 8] nodename nor servname provided, or not known

During handling of the above exception, another exception occurred:

Traceback (most recent call last):
  File "/Users/ulisesv/Desktop/chewbacca/backend/api/src/database/db_mysql.py", line 9, in get_connection
    return pymysql.connect(
           ^^^^^^^^^^^^^^^^
  File "/Library/Frameworks/Python.framework/Versions/3.12/lib/python3.12/site-packages/pymysql/connections.py", line 358, in __init__
    self.connect()
  File "/Library/Frameworks/Python.framework/Versions/3.12/lib/python3.12/site-packages/pymysql/connections.py", line 711, in connect
    raise exc
pymysql.err.OperationalError: (2003, "Can't connect to MySQL server on 'mysql' ([Errno 8] nodename nor servname provided, or not known)")

2024-05-10 09:44:41 | ERROR | 'NoneType' object has no attribute 'cursor'
2024-05-10 09:44:41 | ERROR | Traceback (most recent call last):
  File "/Users/ulisesv/Desktop/chewbacca/backend/api/src/services/people.py", line 14, in get_people
    results = get_people_pagination(page)
              ^^^^^^^^^^^^^^^^^^^^^^^^^^^
  File "/Users/ulisesv/Desktop/chewbacca/backend/api/src/controllers/people.py", line 30, in get_people_pagination
    with conexion.cursor() as cursor:
         ^^^^^^^^^^^^^^^
AttributeError: 'NoneType' object has no attribute 'cursor'

2024-05-10 09:44:43 | ERROR | (2003, "Can't connect to MySQL server on 'mysql' ([Errno 8] nodename nor servname provided, or not known)")
2024-05-10 09:44:43 | ERROR | Traceback (most recent call last):
  File "/Library/Frameworks/Python.framework/Versions/3.12/lib/python3.12/site-packages/pymysql/connections.py", line 644, in connect
    sock = socket.create_connection(
           ^^^^^^^^^^^^^^^^^^^^^^^^^
  File "/Library/Frameworks/Python.framework/Versions/3.12/lib/python3.12/socket.py", line 828, in create_connection
    for res in getaddrinfo(host, port, 0, SOCK_STREAM):
               ^^^^^^^^^^^^^^^^^^^^^^^^^^^^^^^^^^^^^^^
  File "/Library/Frameworks/Python.framework/Versions/3.12/lib/python3.12/socket.py", line 963, in getaddrinfo
    for res in _socket.getaddrinfo(host, port, family, type, proto, flags):
               ^^^^^^^^^^^^^^^^^^^^^^^^^^^^^^^^^^^^^^^^^^^^^^^^^^^^^^^^^^^
socket.gaierror: [Errno 8] nodename nor servname provided, or not known

During handling of the above exception, another exception occurred:

Traceback (most recent call last):
  File "/Users/ulisesv/Desktop/chewbacca/backend/api/src/database/db_mysql.py", line 9, in get_connection
    return pymysql.connect(
           ^^^^^^^^^^^^^^^^
  File "/Library/Frameworks/Python.framework/Versions/3.12/lib/python3.12/site-packages/pymysql/connections.py", line 358, in __init__
    self.connect()
  File "/Library/Frameworks/Python.framework/Versions/3.12/lib/python3.12/site-packages/pymysql/connections.py", line 711, in connect
    raise exc
pymysql.err.OperationalError: (2003, "Can't connect to MySQL server on 'mysql' ([Errno 8] nodename nor servname provided, or not known)")

2024-05-10 09:44:43 | ERROR | 'NoneType' object has no attribute 'cursor'
2024-05-10 09:44:43 | ERROR | Traceback (most recent call last):
  File "/Users/ulisesv/Desktop/chewbacca/backend/api/src/services/people.py", line 14, in get_people
    results = get_people_pagination(page)
              ^^^^^^^^^^^^^^^^^^^^^^^^^^^
  File "/Users/ulisesv/Desktop/chewbacca/backend/api/src/controllers/people.py", line 30, in get_people_pagination
    with conexion.cursor() as cursor:
         ^^^^^^^^^^^^^^^
AttributeError: 'NoneType' object has no attribute 'cursor'

2024-05-10 09:44:55 | ERROR | (2003, "Can't connect to MySQL server on 'JAJAJAJA' ([Errno 8] nodename nor servname provided, or not known)")
2024-05-10 09:44:55 | ERROR | Traceback (most recent call last):
  File "/Library/Frameworks/Python.framework/Versions/3.12/lib/python3.12/site-packages/pymysql/connections.py", line 644, in connect
    sock = socket.create_connection(
           ^^^^^^^^^^^^^^^^^^^^^^^^^
  File "/Library/Frameworks/Python.framework/Versions/3.12/lib/python3.12/socket.py", line 828, in create_connection
    for res in getaddrinfo(host, port, 0, SOCK_STREAM):
               ^^^^^^^^^^^^^^^^^^^^^^^^^^^^^^^^^^^^^^^
  File "/Library/Frameworks/Python.framework/Versions/3.12/lib/python3.12/socket.py", line 963, in getaddrinfo
    for res in _socket.getaddrinfo(host, port, family, type, proto, flags):
               ^^^^^^^^^^^^^^^^^^^^^^^^^^^^^^^^^^^^^^^^^^^^^^^^^^^^^^^^^^^
socket.gaierror: [Errno 8] nodename nor servname provided, or not known

During handling of the above exception, another exception occurred:

Traceback (most recent call last):
  File "/Users/ulisesv/Desktop/chewbacca/backend/api/src/database/db_mysql.py", line 9, in get_connection
    return pymysql.connect(
           ^^^^^^^^^^^^^^^^
  File "/Library/Frameworks/Python.framework/Versions/3.12/lib/python3.12/site-packages/pymysql/connections.py", line 358, in __init__
    self.connect()
  File "/Library/Frameworks/Python.framework/Versions/3.12/lib/python3.12/site-packages/pymysql/connections.py", line 711, in connect
    raise exc
pymysql.err.OperationalError: (2003, "Can't connect to MySQL server on 'JAJAJAJA' ([Errno 8] nodename nor servname provided, or not known)")

2024-05-10 09:44:55 | ERROR | 'NoneType' object has no attribute 'cursor'
2024-05-10 09:44:55 | ERROR | Traceback (most recent call last):
  File "/Users/ulisesv/Desktop/chewbacca/backend/api/src/services/people.py", line 14, in get_people
    results = get_people_pagination(page)
              ^^^^^^^^^^^^^^^^^^^^^^^^^^^
  File "/Users/ulisesv/Desktop/chewbacca/backend/api/src/controllers/people.py", line 30, in get_people_pagination
    with conexion.cursor() as cursor:
         ^^^^^^^^^^^^^^^
AttributeError: 'NoneType' object has no attribute 'cursor'

2024-05-10 09:45:08 | ERROR | (2003, "Can't connect to MySQL server on 'MySQL' ([Errno 8] nodename nor servname provided, or not known)")
2024-05-10 09:45:08 | ERROR | Traceback (most recent call last):
  File "/Library/Frameworks/Python.framework/Versions/3.12/lib/python3.12/site-packages/pymysql/connections.py", line 644, in connect
    sock = socket.create_connection(
           ^^^^^^^^^^^^^^^^^^^^^^^^^
  File "/Library/Frameworks/Python.framework/Versions/3.12/lib/python3.12/socket.py", line 828, in create_connection
    for res in getaddrinfo(host, port, 0, SOCK_STREAM):
               ^^^^^^^^^^^^^^^^^^^^^^^^^^^^^^^^^^^^^^^
  File "/Library/Frameworks/Python.framework/Versions/3.12/lib/python3.12/socket.py", line 963, in getaddrinfo
    for res in _socket.getaddrinfo(host, port, family, type, proto, flags):
               ^^^^^^^^^^^^^^^^^^^^^^^^^^^^^^^^^^^^^^^^^^^^^^^^^^^^^^^^^^^
socket.gaierror: [Errno 8] nodename nor servname provided, or not known

During handling of the above exception, another exception occurred:

Traceback (most recent call last):
  File "/Users/ulisesv/Desktop/chewbacca/backend/api/src/database/db_mysql.py", line 9, in get_connection
    return pymysql.connect(
           ^^^^^^^^^^^^^^^^
  File "/Library/Frameworks/Python.framework/Versions/3.12/lib/python3.12/site-packages/pymysql/connections.py", line 358, in __init__
    self.connect()
  File "/Library/Frameworks/Python.framework/Versions/3.12/lib/python3.12/site-packages/pymysql/connections.py", line 711, in connect
    raise exc
pymysql.err.OperationalError: (2003, "Can't connect to MySQL server on 'MySQL' ([Errno 8] nodename nor servname provided, or not known)")

2024-05-10 09:45:08 | ERROR | 'NoneType' object has no attribute 'cursor'
2024-05-10 09:45:08 | ERROR | Traceback (most recent call last):
  File "/Users/ulisesv/Desktop/chewbacca/backend/api/src/services/people.py", line 14, in get_people
    results = get_people_pagination(page)
              ^^^^^^^^^^^^^^^^^^^^^^^^^^^
  File "/Users/ulisesv/Desktop/chewbacca/backend/api/src/controllers/people.py", line 30, in get_people_pagination
    with conexion.cursor() as cursor:
         ^^^^^^^^^^^^^^^
AttributeError: 'NoneType' object has no attribute 'cursor'

2024-05-10 09:45:16 | ERROR | (2003, "Can't connect to MySQL server on 'MySQL' ([Errno 8] nodename nor servname provided, or not known)")
2024-05-10 09:45:16 | ERROR | Traceback (most recent call last):
  File "/Library/Frameworks/Python.framework/Versions/3.12/lib/python3.12/site-packages/pymysql/connections.py", line 644, in connect
    sock = socket.create_connection(
           ^^^^^^^^^^^^^^^^^^^^^^^^^
  File "/Library/Frameworks/Python.framework/Versions/3.12/lib/python3.12/socket.py", line 828, in create_connection
    for res in getaddrinfo(host, port, 0, SOCK_STREAM):
               ^^^^^^^^^^^^^^^^^^^^^^^^^^^^^^^^^^^^^^^
  File "/Library/Frameworks/Python.framework/Versions/3.12/lib/python3.12/socket.py", line 963, in getaddrinfo
    for res in _socket.getaddrinfo(host, port, family, type, proto, flags):
               ^^^^^^^^^^^^^^^^^^^^^^^^^^^^^^^^^^^^^^^^^^^^^^^^^^^^^^^^^^^
socket.gaierror: [Errno 8] nodename nor servname provided, or not known

During handling of the above exception, another exception occurred:

Traceback (most recent call last):
  File "/Users/ulisesv/Desktop/chewbacca/backend/api/src/database/db_mysql.py", line 9, in get_connection
    return pymysql.connect(
           ^^^^^^^^^^^^^^^^
  File "/Library/Frameworks/Python.framework/Versions/3.12/lib/python3.12/site-packages/pymysql/connections.py", line 358, in __init__
    self.connect()
  File "/Library/Frameworks/Python.framework/Versions/3.12/lib/python3.12/site-packages/pymysql/connections.py", line 711, in connect
    raise exc
pymysql.err.OperationalError: (2003, "Can't connect to MySQL server on 'MySQL' ([Errno 8] nodename nor servname provided, or not known)")

2024-05-10 09:45:16 | ERROR | 'NoneType' object has no attribute 'cursor'
2024-05-10 09:45:16 | ERROR | Traceback (most recent call last):
  File "/Users/ulisesv/Desktop/chewbacca/backend/api/src/services/people.py", line 14, in get_people
    results = get_people_pagination(page)
              ^^^^^^^^^^^^^^^^^^^^^^^^^^^
  File "/Users/ulisesv/Desktop/chewbacca/backend/api/src/controllers/people.py", line 30, in get_people_pagination
    with conexion.cursor() as cursor:
         ^^^^^^^^^^^^^^^
AttributeError: 'NoneType' object has no attribute 'cursor'

2024-05-10 09:47:23 | ERROR | name 'console' is not defined
2024-05-10 10:19:27 | ERROR | cannot convert dictionary update sequence element #0 to a sequence
2024-05-10 10:19:27 | ERROR | Traceback (most recent call last):
  File "/Users/ulisesv/Desktop/chewbacca/backend/api/src/services/people.py", line 13, in get_people
    results = get_people_pagination(page)
              ^^^^^^^^^^^^^^^^^^^^^^^^^^^
  File "/Users/ulisesv/Desktop/chewbacca/backend/api/src/controllers/people.py", line 22, in get_people_pagination
    return json.dumps( [dict(ix) for ix in result] )
                       ^^^^^^^^
TypeError: cannot convert dictionary update sequence element #0 to a sequence

2024-05-10 10:20:20 | ERROR | cannot convert dictionary update sequence element #0 to a sequence
2024-05-10 10:20:20 | ERROR | Traceback (most recent call last):
  File "/Users/ulisesv/Desktop/chewbacca/backend/api/src/services/people.py", line 13, in get_people
    results = get_people_pagination(page)
              ^^^^^^^^^^^^^^^^^^^^^^^^^^^
  File "/Users/ulisesv/Desktop/chewbacca/backend/api/src/controllers/people.py", line 22, in get_people_pagination
    ok = json.dumps( [dict(ix) for ix in result] )
                     ^^^^^^^^
TypeError: cannot convert dictionary update sequence element #0 to a sequence

2024-05-10 10:22:14 | ERROR | 'int' object has no attribute 'fetchall'
2024-05-10 10:22:14 | ERROR | Traceback (most recent call last):
  File "/Users/ulisesv/Desktop/chewbacca/backend/api/src/services/people.py", line 13, in get_people
    results = get_people_pagination(page)
              ^^^^^^^^^^^^^^^^^^^^^^^^^^^
  File "/Users/ulisesv/Desktop/chewbacca/backend/api/src/controllers/people.py", line 19, in get_people_pagination
    result = cursor.execute("SELECT * FROM people limit %s, %s;", (startat, perpage)).fetchall()
             ^^^^^^^^^^^^^^^^^^^^^^^^^^^^^^^^^^^^^^^^^^^^^^^^^^^^^^^^^^^^^^^^^^^^^^^^^^^^^^^^^
AttributeError: 'int' object has no attribute 'fetchall'

2024-05-10 10:22:24 | ERROR | 'int' object has no attribute 'fetchall'
2024-05-10 10:22:24 | ERROR | Traceback (most recent call last):
  File "/Users/ulisesv/Desktop/chewbacca/backend/api/src/services/people.py", line 13, in get_people
    results = get_people_pagination(page)
              ^^^^^^^^^^^^^^^^^^^^^^^^^^^
  File "/Users/ulisesv/Desktop/chewbacca/backend/api/src/controllers/people.py", line 19, in get_people_pagination
    result = cursor.execute("SELECT * FROM people limit %s, %s;", (startat, perpage)).fetchall()
             ^^^^^^^^^^^^^^^^^^^^^^^^^^^^^^^^^^^^^^^^^^^^^^^^^^^^^^^^^^^^^^^^^^^^^^^^^^^^^^^^^
AttributeError: 'int' object has no attribute 'fetchall'

2024-05-10 10:22:24 | ERROR | 'int' object has no attribute 'fetchall'
2024-05-10 10:22:24 | ERROR | Traceback (most recent call last):
  File "/Users/ulisesv/Desktop/chewbacca/backend/api/src/services/people.py", line 13, in get_people
    results = get_people_pagination(page)
              ^^^^^^^^^^^^^^^^^^^^^^^^^^^
  File "/Users/ulisesv/Desktop/chewbacca/backend/api/src/controllers/people.py", line 19, in get_people_pagination
    result = cursor.execute("SELECT * FROM people limit %s, %s;", (startat, perpage)).fetchall()
             ^^^^^^^^^^^^^^^^^^^^^^^^^^^^^^^^^^^^^^^^^^^^^^^^^^^^^^^^^^^^^^^^^^^^^^^^^^^^^^^^^
AttributeError: 'int' object has no attribute 'fetchall'

2024-05-10 10:22:38 | ERROR | 'int' object has no attribute 'fetchall'
2024-05-10 10:22:38 | ERROR | Traceback (most recent call last):
  File "/Users/ulisesv/Desktop/chewbacca/backend/api/src/services/people.py", line 13, in get_people
    results = get_people_pagination(page)
              ^^^^^^^^^^^^^^^^^^^^^^^^^^^
  File "/Users/ulisesv/Desktop/chewbacca/backend/api/src/controllers/people.py", line 19, in get_people_pagination
    result = cursor.execute("SELECT * FROM people limit %s, %s;", (startat, perpage)).fetchall()
             ^^^^^^^^^^^^^^^^^^^^^^^^^^^^^^^^^^^^^^^^^^^^^^^^^^^^^^^^^^^^^^^^^^^^^^^^^^^^^^^^^
AttributeError: 'int' object has no attribute 'fetchall'

2024-05-10 10:22:48 | ERROR | 'int' object has no attribute 'fetchall'
2024-05-10 10:22:48 | ERROR | Traceback (most recent call last):
  File "/Users/ulisesv/Desktop/chewbacca/backend/api/src/services/people.py", line 13, in get_people
    results = get_people_pagination(page)
              ^^^^^^^^^^^^^^^^^^^^^^^^^^^
  File "/Users/ulisesv/Desktop/chewbacca/backend/api/src/controllers/people.py", line 19, in get_people_pagination
    result = cursor.execute("SELECT * FROM people limit %s, %s;", (startat, perpage)).fetchall()
             ^^^^^^^^^^^^^^^^^^^^^^^^^^^^^^^^^^^^^^^^^^^^^^^^^^^^^^^^^^^^^^^^^^^^^^^^^^^^^^^^^
AttributeError: 'int' object has no attribute 'fetchall'

2024-05-10 10:22:49 | ERROR | 'int' object has no attribute 'fetchall'
2024-05-10 10:22:49 | ERROR | Traceback (most recent call last):
  File "/Users/ulisesv/Desktop/chewbacca/backend/api/src/services/people.py", line 13, in get_people
    results = get_people_pagination(page)
              ^^^^^^^^^^^^^^^^^^^^^^^^^^^
  File "/Users/ulisesv/Desktop/chewbacca/backend/api/src/controllers/people.py", line 19, in get_people_pagination
    result = cursor.execute("SELECT * FROM people limit %s, %s;", (startat, perpage)).fetchall()
             ^^^^^^^^^^^^^^^^^^^^^^^^^^^^^^^^^^^^^^^^^^^^^^^^^^^^^^^^^^^^^^^^^^^^^^^^^^^^^^^^^
AttributeError: 'int' object has no attribute 'fetchall'

2024-05-10 10:22:50 | ERROR | 'int' object has no attribute 'fetchall'
2024-05-10 10:22:50 | ERROR | Traceback (most recent call last):
  File "/Users/ulisesv/Desktop/chewbacca/backend/api/src/services/people.py", line 13, in get_people
    results = get_people_pagination(page)
              ^^^^^^^^^^^^^^^^^^^^^^^^^^^
  File "/Users/ulisesv/Desktop/chewbacca/backend/api/src/controllers/people.py", line 19, in get_people_pagination
    result = cursor.execute("SELECT * FROM people limit %s, %s;", (startat, perpage)).fetchall()
             ^^^^^^^^^^^^^^^^^^^^^^^^^^^^^^^^^^^^^^^^^^^^^^^^^^^^^^^^^^^^^^^^^^^^^^^^^^^^^^^^^
AttributeError: 'int' object has no attribute 'fetchall'

2024-05-10 10:23:11 | ERROR | 'int' object has no attribute 'fetchall'
2024-05-10 10:23:11 | ERROR | Traceback (most recent call last):
  File "/Users/ulisesv/Desktop/chewbacca/backend/api/src/services/people.py", line 13, in get_people
    results = get_people_pagination(page)
              ^^^^^^^^^^^^^^^^^^^^^^^^^^^
  File "/Users/ulisesv/Desktop/chewbacca/backend/api/src/controllers/people.py", line 20, in get_people_pagination
    result = cursor.execute("SELECT * FROM people limit %s, %s;", (startat, perpage)).fetchall()
             ^^^^^^^^^^^^^^^^^^^^^^^^^^^^^^^^^^^^^^^^^^^^^^^^^^^^^^^^^^^^^^^^^^^^^^^^^^^^^^^^^
AttributeError: 'int' object has no attribute 'fetchall'

2024-05-10 10:23:31 | ERROR | 'int' object has no attribute 'fetchall'
2024-05-10 10:23:31 | ERROR | Traceback (most recent call last):
  File "/Users/ulisesv/Desktop/chewbacca/backend/api/src/services/people.py", line 13, in get_people
    results = get_people_pagination(page)
              ^^^^^^^^^^^^^^^^^^^^^^^^^^^
  File "/Users/ulisesv/Desktop/chewbacca/backend/api/src/controllers/people.py", line 20, in get_people_pagination
    result = cursor.execute("SELECT * FROM people limit %s, %s;", (startat, perpage)).fetchall()
             ^^^^^^^^^^^^^^^^^^^^^^^^^^^^^^^^^^^^^^^^^^^^^^^^^^^^^^^^^^^^^^^^^^^^^^^^^^^^^^^^^
AttributeError: 'int' object has no attribute 'fetchall'

2024-05-10 10:24:35 | ERROR | Object of type datetime is not JSON serializable
2024-05-10 10:24:35 | ERROR | Traceback (most recent call last):
  File "/Users/ulisesv/Desktop/chewbacca/backend/api/src/services/people.py", line 13, in get_people
    results = get_people_pagination(page)
              ^^^^^^^^^^^^^^^^^^^^^^^^^^^
  File "/Users/ulisesv/Desktop/chewbacca/backend/api/src/controllers/people.py", line 22, in get_people_pagination
    print(json.dumps(result))
          ^^^^^^^^^^^^^^^^^^
  File "/Library/Frameworks/Python.framework/Versions/3.12/lib/python3.12/json/__init__.py", line 231, in dumps
    return _default_encoder.encode(obj)
           ^^^^^^^^^^^^^^^^^^^^^^^^^^^^
  File "/Library/Frameworks/Python.framework/Versions/3.12/lib/python3.12/json/encoder.py", line 200, in encode
    chunks = self.iterencode(o, _one_shot=True)
             ^^^^^^^^^^^^^^^^^^^^^^^^^^^^^^^^^^
  File "/Library/Frameworks/Python.framework/Versions/3.12/lib/python3.12/json/encoder.py", line 258, in iterencode
    return _iterencode(o, 0)
           ^^^^^^^^^^^^^^^^^
  File "/Library/Frameworks/Python.framework/Versions/3.12/lib/python3.12/json/encoder.py", line 180, in default
    raise TypeError(f'Object of type {o.__class__.__name__} '
TypeError: Object of type datetime is not JSON serializable

2024-05-10 10:24:38 | ERROR | Object of type datetime is not JSON serializable
2024-05-10 10:24:38 | ERROR | Traceback (most recent call last):
  File "/Users/ulisesv/Desktop/chewbacca/backend/api/src/services/people.py", line 13, in get_people
    results = get_people_pagination(page)
              ^^^^^^^^^^^^^^^^^^^^^^^^^^^
  File "/Users/ulisesv/Desktop/chewbacca/backend/api/src/controllers/people.py", line 22, in get_people_pagination
    print(json.dumps(result))
          ^^^^^^^^^^^^^^^^^^
  File "/Library/Frameworks/Python.framework/Versions/3.12/lib/python3.12/json/__init__.py", line 231, in dumps
    return _default_encoder.encode(obj)
           ^^^^^^^^^^^^^^^^^^^^^^^^^^^^
  File "/Library/Frameworks/Python.framework/Versions/3.12/lib/python3.12/json/encoder.py", line 200, in encode
    chunks = self.iterencode(o, _one_shot=True)
             ^^^^^^^^^^^^^^^^^^^^^^^^^^^^^^^^^^
  File "/Library/Frameworks/Python.framework/Versions/3.12/lib/python3.12/json/encoder.py", line 258, in iterencode
    return _iterencode(o, 0)
           ^^^^^^^^^^^^^^^^^
  File "/Library/Frameworks/Python.framework/Versions/3.12/lib/python3.12/json/encoder.py", line 180, in default
    raise TypeError(f'Object of type {o.__class__.__name__} '
TypeError: Object of type datetime is not JSON serializable

2024-05-10 11:12:26 | ERROR | cannot access local variable 'result' where it is not associated with a value
2024-05-10 11:12:26 | ERROR | Traceback (most recent call last):
  File "/Users/ulisesv/Desktop/chewbacca/backend/api/src/services/people.py", line 13, in get_people
    results = get_people_pagination(page)
              ^^^^^^^^^^^^^^^^^^^^^^^^^^^
  File "/Users/ulisesv/Desktop/chewbacca/backend/api/src/controllers/people.py", line 23, in get_people_pagination
    print(json.dumps(result))
                     ^^^^^^
UnboundLocalError: cannot access local variable 'result' where it is not associated with a value

2024-05-10 11:13:17 | ERROR | cannot access local variable 'result' where it is not associated with a value
2024-05-10 11:13:17 | ERROR | Traceback (most recent call last):
  File "/Users/ulisesv/Desktop/chewbacca/backend/api/src/services/people.py", line 13, in get_people
    results = get_people_pagination(page)
              ^^^^^^^^^^^^^^^^^^^^^^^^^^^
  File "/Users/ulisesv/Desktop/chewbacca/backend/api/src/controllers/people.py", line 23, in get_people_pagination
    print(json.dumps(result))
                     ^^^^^^
UnboundLocalError: cannot access local variable 'result' where it is not associated with a value

2024-05-10 11:15:00 | ERROR | Object of type datetime is not JSON serializable
2024-05-10 11:15:00 | ERROR | Traceback (most recent call last):
  File "/Users/ulisesv/Desktop/chewbacca/backend/api/src/services/people.py", line 13, in get_people
    results = get_people_pagination(page)
              ^^^^^^^^^^^^^^^^^^^^^^^^^^^
  File "/Users/ulisesv/Desktop/chewbacca/backend/api/src/controllers/people.py", line 34, in get_people_pagination
    json_result = json.dumps(result)
                  ^^^^^^^^^^^^^^^^^^
  File "/Library/Frameworks/Python.framework/Versions/3.12/lib/python3.12/json/__init__.py", line 231, in dumps
    return _default_encoder.encode(obj)
           ^^^^^^^^^^^^^^^^^^^^^^^^^^^^
  File "/Library/Frameworks/Python.framework/Versions/3.12/lib/python3.12/json/encoder.py", line 200, in encode
    chunks = self.iterencode(o, _one_shot=True)
             ^^^^^^^^^^^^^^^^^^^^^^^^^^^^^^^^^^
  File "/Library/Frameworks/Python.framework/Versions/3.12/lib/python3.12/json/encoder.py", line 258, in iterencode
    return _iterencode(o, 0)
           ^^^^^^^^^^^^^^^^^
  File "/Library/Frameworks/Python.framework/Versions/3.12/lib/python3.12/json/encoder.py", line 180, in default
    raise TypeError(f'Object of type {o.__class__.__name__} '
TypeError: Object of type datetime is not JSON serializable

2024-05-10 11:19:18 | ERROR | name 'result' is not defined
2024-05-10 11:19:19 | ERROR | Traceback (most recent call last):
  File "/Users/ulisesv/Desktop/chewbacca/backend/api/src/services/people.py", line 13, in get_people
    results = get_people_pagination(page)
              ^^^^^^^^^^^^^^^^^^^^^^^^^^^
  File "/Users/ulisesv/Desktop/chewbacca/backend/api/src/controllers/people.py", line 39, in get_people_pagination
    return result
           ^^^^^^
NameError: name 'result' is not defined

2024-05-10 11:31:22 | ERROR | name 'result' is not defined
2024-05-10 11:31:22 | ERROR | Traceback (most recent call last):
  File "/Users/ulisesv/Desktop/chewbacca/backend/api/src/services/people.py", line 13, in get_people
    results = get_people_pagination(page)
              ^^^^^^^^^^^^^^^^^^^^^^^^^^^
  File "/Users/ulisesv/Desktop/chewbacca/backend/api/src/controllers/people.py", line 39, in get_people_pagination
    return result
           ^^^^^^
NameError: name 'result' is not defined

2024-05-10 11:31:39 | ERROR | name 'result' is not defined
2024-05-10 11:31:39 | ERROR | Traceback (most recent call last):
  File "/Users/ulisesv/Desktop/chewbacca/backend/api/src/services/people.py", line 13, in get_people
    results = get_people_pagination(page)
              ^^^^^^^^^^^^^^^^^^^^^^^^^^^
  File "/Users/ulisesv/Desktop/chewbacca/backend/api/src/controllers/people.py", line 39, in get_people_pagination
    return result
           ^^^^^^
NameError: name 'result' is not defined

2024-05-10 11:34:25 | ERROR | Object of type datetime is not JSON serializable
2024-05-10 11:34:25 | ERROR | Traceback (most recent call last):
  File "/Users/ulisesv/Desktop/chewbacca/backend/api/src/services/people.py", line 13, in get_people
    results = get_people_pagination(page)
              ^^^^^^^^^^^^^^^^^^^^^^^^^^^
  File "/Users/ulisesv/Desktop/chewbacca/backend/api/src/controllers/people.py", line 23, in get_people_pagination
    json_result = json.dumps(data)
                  ^^^^^^^^^^^^^^^^
  File "/Library/Frameworks/Python.framework/Versions/3.12/lib/python3.12/json/__init__.py", line 231, in dumps
    return _default_encoder.encode(obj)
           ^^^^^^^^^^^^^^^^^^^^^^^^^^^^
  File "/Library/Frameworks/Python.framework/Versions/3.12/lib/python3.12/json/encoder.py", line 200, in encode
    chunks = self.iterencode(o, _one_shot=True)
             ^^^^^^^^^^^^^^^^^^^^^^^^^^^^^^^^^^
  File "/Library/Frameworks/Python.framework/Versions/3.12/lib/python3.12/json/encoder.py", line 258, in iterencode
    return _iterencode(o, 0)
           ^^^^^^^^^^^^^^^^^
  File "/Library/Frameworks/Python.framework/Versions/3.12/lib/python3.12/json/encoder.py", line 180, in default
    raise TypeError(f'Object of type {o.__class__.__name__} '
TypeError: Object of type datetime is not JSON serializable

2024-05-10 11:34:26 | ERROR | Object of type datetime is not JSON serializable
2024-05-10 11:34:26 | ERROR | Traceback (most recent call last):
  File "/Users/ulisesv/Desktop/chewbacca/backend/api/src/services/people.py", line 13, in get_people
    results = get_people_pagination(page)
              ^^^^^^^^^^^^^^^^^^^^^^^^^^^
  File "/Users/ulisesv/Desktop/chewbacca/backend/api/src/controllers/people.py", line 23, in get_people_pagination
    json_result = json.dumps(data)
                  ^^^^^^^^^^^^^^^^
  File "/Library/Frameworks/Python.framework/Versions/3.12/lib/python3.12/json/__init__.py", line 231, in dumps
    return _default_encoder.encode(obj)
           ^^^^^^^^^^^^^^^^^^^^^^^^^^^^
  File "/Library/Frameworks/Python.framework/Versions/3.12/lib/python3.12/json/encoder.py", line 200, in encode
    chunks = self.iterencode(o, _one_shot=True)
             ^^^^^^^^^^^^^^^^^^^^^^^^^^^^^^^^^^
  File "/Library/Frameworks/Python.framework/Versions/3.12/lib/python3.12/json/encoder.py", line 258, in iterencode
    return _iterencode(o, 0)
           ^^^^^^^^^^^^^^^^^
  File "/Library/Frameworks/Python.framework/Versions/3.12/lib/python3.12/json/encoder.py", line 180, in default
    raise TypeError(f'Object of type {o.__class__.__name__} '
TypeError: Object of type datetime is not JSON serializable

2024-05-10 11:34:32 | ERROR | Object of type datetime is not JSON serializable
2024-05-10 11:34:32 | ERROR | Traceback (most recent call last):
  File "/Users/ulisesv/Desktop/chewbacca/backend/api/src/services/people.py", line 13, in get_people
    results = get_people_pagination(page)
              ^^^^^^^^^^^^^^^^^^^^^^^^^^^
  File "/Users/ulisesv/Desktop/chewbacca/backend/api/src/controllers/people.py", line 23, in get_people_pagination
    json_result = json.dumps(data)
                  ^^^^^^^^^^^^^^^^
  File "/Library/Frameworks/Python.framework/Versions/3.12/lib/python3.12/json/__init__.py", line 231, in dumps
    return _default_encoder.encode(obj)
           ^^^^^^^^^^^^^^^^^^^^^^^^^^^^
  File "/Library/Frameworks/Python.framework/Versions/3.12/lib/python3.12/json/encoder.py", line 200, in encode
    chunks = self.iterencode(o, _one_shot=True)
             ^^^^^^^^^^^^^^^^^^^^^^^^^^^^^^^^^^
  File "/Library/Frameworks/Python.framework/Versions/3.12/lib/python3.12/json/encoder.py", line 258, in iterencode
    return _iterencode(o, 0)
           ^^^^^^^^^^^^^^^^^
  File "/Library/Frameworks/Python.framework/Versions/3.12/lib/python3.12/json/encoder.py", line 180, in default
    raise TypeError(f'Object of type {o.__class__.__name__} '
TypeError: Object of type datetime is not JSON serializable

2024-05-10 11:36:32 | ERROR | (1064, "You have an error in your SQL syntax; check the manual that corresponds to your MySQL server version for the right syntax to use near 'limit 10, 10' at line 1")
2024-05-10 11:36:32 | ERROR | Traceback (most recent call last):
  File "/Users/ulisesv/Desktop/chewbacca/backend/api/src/services/people.py", line 13, in get_people
    results = get_people_pagination(page)
              ^^^^^^^^^^^^^^^^^^^^^^^^^^^
  File "/Users/ulisesv/Desktop/chewbacca/backend/api/src/controllers/people.py", line 20, in get_people_pagination
    cursor.execute("SELECT name, height, mass, hairColor, gender, dob, img FROM limit %s, %s;", (startat, perpage))
  File "/Library/Frameworks/Python.framework/Versions/3.12/lib/python3.12/site-packages/pymysql/cursors.py", line 153, in execute
    result = self._query(query)
             ^^^^^^^^^^^^^^^^^^
  File "/Library/Frameworks/Python.framework/Versions/3.12/lib/python3.12/site-packages/pymysql/cursors.py", line 322, in _query
    conn.query(q)
  File "/Library/Frameworks/Python.framework/Versions/3.12/lib/python3.12/site-packages/pymysql/connections.py", line 558, in query
    self._affected_rows = self._read_query_result(unbuffered=unbuffered)
                          ^^^^^^^^^^^^^^^^^^^^^^^^^^^^^^^^^^^^^^^^^^^^^^
  File "/Library/Frameworks/Python.framework/Versions/3.12/lib/python3.12/site-packages/pymysql/connections.py", line 822, in _read_query_result
    result.read()
  File "/Library/Frameworks/Python.framework/Versions/3.12/lib/python3.12/site-packages/pymysql/connections.py", line 1200, in read
    first_packet = self.connection._read_packet()
                   ^^^^^^^^^^^^^^^^^^^^^^^^^^^^^^
  File "/Library/Frameworks/Python.framework/Versions/3.12/lib/python3.12/site-packages/pymysql/connections.py", line 772, in _read_packet
    packet.raise_for_error()
  File "/Library/Frameworks/Python.framework/Versions/3.12/lib/python3.12/site-packages/pymysql/protocol.py", line 221, in raise_for_error
    err.raise_mysql_exception(self._data)
  File "/Library/Frameworks/Python.framework/Versions/3.12/lib/python3.12/site-packages/pymysql/err.py", line 143, in raise_mysql_exception
    raise errorclass(errno, errval)
pymysql.err.ProgrammingError: (1064, "You have an error in your SQL syntax; check the manual that corresponds to your MySQL server version for the right syntax to use near 'limit 10, 10' at line 1")

2024-05-10 11:36:33 | ERROR | (1064, "You have an error in your SQL syntax; check the manual that corresponds to your MySQL server version for the right syntax to use near 'limit 10, 10' at line 1")
2024-05-10 11:36:33 | ERROR | Traceback (most recent call last):
  File "/Users/ulisesv/Desktop/chewbacca/backend/api/src/services/people.py", line 13, in get_people
    results = get_people_pagination(page)
              ^^^^^^^^^^^^^^^^^^^^^^^^^^^
  File "/Users/ulisesv/Desktop/chewbacca/backend/api/src/controllers/people.py", line 20, in get_people_pagination
    cursor.execute("SELECT name, height, mass, hairColor, gender, dob, img FROM limit %s, %s;", (startat, perpage))
  File "/Library/Frameworks/Python.framework/Versions/3.12/lib/python3.12/site-packages/pymysql/cursors.py", line 153, in execute
    result = self._query(query)
             ^^^^^^^^^^^^^^^^^^
  File "/Library/Frameworks/Python.framework/Versions/3.12/lib/python3.12/site-packages/pymysql/cursors.py", line 322, in _query
    conn.query(q)
  File "/Library/Frameworks/Python.framework/Versions/3.12/lib/python3.12/site-packages/pymysql/connections.py", line 558, in query
    self._affected_rows = self._read_query_result(unbuffered=unbuffered)
                          ^^^^^^^^^^^^^^^^^^^^^^^^^^^^^^^^^^^^^^^^^^^^^^
  File "/Library/Frameworks/Python.framework/Versions/3.12/lib/python3.12/site-packages/pymysql/connections.py", line 822, in _read_query_result
    result.read()
  File "/Library/Frameworks/Python.framework/Versions/3.12/lib/python3.12/site-packages/pymysql/connections.py", line 1200, in read
    first_packet = self.connection._read_packet()
                   ^^^^^^^^^^^^^^^^^^^^^^^^^^^^^^
  File "/Library/Frameworks/Python.framework/Versions/3.12/lib/python3.12/site-packages/pymysql/connections.py", line 772, in _read_packet
    packet.raise_for_error()
  File "/Library/Frameworks/Python.framework/Versions/3.12/lib/python3.12/site-packages/pymysql/protocol.py", line 221, in raise_for_error
    err.raise_mysql_exception(self._data)
  File "/Library/Frameworks/Python.framework/Versions/3.12/lib/python3.12/site-packages/pymysql/err.py", line 143, in raise_mysql_exception
    raise errorclass(errno, errval)
pymysql.err.ProgrammingError: (1064, "You have an error in your SQL syntax; check the manual that corresponds to your MySQL server version for the right syntax to use near 'limit 10, 10' at line 1")

2024-05-10 11:36:42 | ERROR | (1064, "You have an error in your SQL syntax; check the manual that corresponds to your MySQL server version for the right syntax to use near 'limit 10, 10' at line 1")
2024-05-10 11:36:42 | ERROR | Traceback (most recent call last):
  File "/Users/ulisesv/Desktop/chewbacca/backend/api/src/services/people.py", line 13, in get_people
    results = get_people_pagination(page)
              ^^^^^^^^^^^^^^^^^^^^^^^^^^^
  File "/Users/ulisesv/Desktop/chewbacca/backend/api/src/controllers/people.py", line 20, in get_people_pagination
    cursor.execute("SELECT name, height, mass, hairColor, gender, dob, img FROM limit %s, %s;", (startat, perpage))
  File "/Library/Frameworks/Python.framework/Versions/3.12/lib/python3.12/site-packages/pymysql/cursors.py", line 153, in execute
    result = self._query(query)
             ^^^^^^^^^^^^^^^^^^
  File "/Library/Frameworks/Python.framework/Versions/3.12/lib/python3.12/site-packages/pymysql/cursors.py", line 322, in _query
    conn.query(q)
  File "/Library/Frameworks/Python.framework/Versions/3.12/lib/python3.12/site-packages/pymysql/connections.py", line 558, in query
    self._affected_rows = self._read_query_result(unbuffered=unbuffered)
                          ^^^^^^^^^^^^^^^^^^^^^^^^^^^^^^^^^^^^^^^^^^^^^^
  File "/Library/Frameworks/Python.framework/Versions/3.12/lib/python3.12/site-packages/pymysql/connections.py", line 822, in _read_query_result
    result.read()
  File "/Library/Frameworks/Python.framework/Versions/3.12/lib/python3.12/site-packages/pymysql/connections.py", line 1200, in read
    first_packet = self.connection._read_packet()
                   ^^^^^^^^^^^^^^^^^^^^^^^^^^^^^^
  File "/Library/Frameworks/Python.framework/Versions/3.12/lib/python3.12/site-packages/pymysql/connections.py", line 772, in _read_packet
    packet.raise_for_error()
  File "/Library/Frameworks/Python.framework/Versions/3.12/lib/python3.12/site-packages/pymysql/protocol.py", line 221, in raise_for_error
    err.raise_mysql_exception(self._data)
  File "/Library/Frameworks/Python.framework/Versions/3.12/lib/python3.12/site-packages/pymysql/err.py", line 143, in raise_mysql_exception
    raise errorclass(errno, errval)
pymysql.err.ProgrammingError: (1064, "You have an error in your SQL syntax; check the manual that corresponds to your MySQL server version for the right syntax to use near 'limit 10, 10' at line 1")

2024-05-10 11:36:58 | ERROR | (1064, "You have an error in your SQL syntax; check the manual that corresponds to your MySQL server version for the right syntax to use near 'limit 10, 10' at line 1")
2024-05-10 11:36:58 | ERROR | Traceback (most recent call last):
  File "/Users/ulisesv/Desktop/chewbacca/backend/api/src/services/people.py", line 13, in get_people
    results = get_people_pagination(page)
              ^^^^^^^^^^^^^^^^^^^^^^^^^^^
  File "/Users/ulisesv/Desktop/chewbacca/backend/api/src/controllers/people.py", line 20, in get_people_pagination
    cursor.execute("SELECT name, height, mass, hairColor, gender, dob, img FROM limit %s, %s;", (startat, perpage))
  File "/Library/Frameworks/Python.framework/Versions/3.12/lib/python3.12/site-packages/pymysql/cursors.py", line 153, in execute
    result = self._query(query)
             ^^^^^^^^^^^^^^^^^^
  File "/Library/Frameworks/Python.framework/Versions/3.12/lib/python3.12/site-packages/pymysql/cursors.py", line 322, in _query
    conn.query(q)
  File "/Library/Frameworks/Python.framework/Versions/3.12/lib/python3.12/site-packages/pymysql/connections.py", line 558, in query
    self._affected_rows = self._read_query_result(unbuffered=unbuffered)
                          ^^^^^^^^^^^^^^^^^^^^^^^^^^^^^^^^^^^^^^^^^^^^^^
  File "/Library/Frameworks/Python.framework/Versions/3.12/lib/python3.12/site-packages/pymysql/connections.py", line 822, in _read_query_result
    result.read()
  File "/Library/Frameworks/Python.framework/Versions/3.12/lib/python3.12/site-packages/pymysql/connections.py", line 1200, in read
    first_packet = self.connection._read_packet()
                   ^^^^^^^^^^^^^^^^^^^^^^^^^^^^^^
  File "/Library/Frameworks/Python.framework/Versions/3.12/lib/python3.12/site-packages/pymysql/connections.py", line 772, in _read_packet
    packet.raise_for_error()
  File "/Library/Frameworks/Python.framework/Versions/3.12/lib/python3.12/site-packages/pymysql/protocol.py", line 221, in raise_for_error
    err.raise_mysql_exception(self._data)
  File "/Library/Frameworks/Python.framework/Versions/3.12/lib/python3.12/site-packages/pymysql/err.py", line 143, in raise_mysql_exception
    raise errorclass(errno, errval)
pymysql.err.ProgrammingError: (1064, "You have an error in your SQL syntax; check the manual that corresponds to your MySQL server version for the right syntax to use near 'limit 10, 10' at line 1")

2024-05-10 11:40:13 | ERROR | string indices must be integers, not 'str'
2024-05-10 11:40:13 | ERROR | Traceback (most recent call last):
  File "/Users/ulisesv/Desktop/chewbacca/backend/api/src/services/people.py", line 13, in get_people
    results = get_people_pagination(page)
              ^^^^^^^^^^^^^^^^^^^^^^^^^^^
  File "/Users/ulisesv/Desktop/chewbacca/backend/api/src/controllers/people.py", line 25, in get_people_pagination
    json_result["people"] = json.loads(json_result["people"])
                                       ~~~~~~~~~~~^^^^^^^^^^
TypeError: string indices must be integers, not 'str'

2024-05-10 11:40:15 | ERROR | string indices must be integers, not 'str'
2024-05-10 11:40:15 | ERROR | Traceback (most recent call last):
  File "/Users/ulisesv/Desktop/chewbacca/backend/api/src/services/people.py", line 13, in get_people
    results = get_people_pagination(page)
              ^^^^^^^^^^^^^^^^^^^^^^^^^^^
  File "/Users/ulisesv/Desktop/chewbacca/backend/api/src/controllers/people.py", line 25, in get_people_pagination
    json_result["people"] = json.loads(json_result["people"])
                                       ~~~~~~~~~~~^^^^^^^^^^
TypeError: string indices must be integers, not 'str'

2024-05-10 11:40:23 | ERROR | string indices must be integers, not 'str'
2024-05-10 11:40:23 | ERROR | Traceback (most recent call last):
  File "/Users/ulisesv/Desktop/chewbacca/backend/api/src/services/people.py", line 13, in get_people
    results = get_people_pagination(page)
              ^^^^^^^^^^^^^^^^^^^^^^^^^^^
  File "/Users/ulisesv/Desktop/chewbacca/backend/api/src/controllers/people.py", line 25, in get_people_pagination
    json_result["people"] = json.loads(json_result["people"])
                                       ~~~~~~~~~~~^^^^^^^^^^
TypeError: string indices must be integers, not 'str'

2024-05-10 11:42:00 | ERROR | (1054, "Unknown column 'id' in 'field list'")
2024-05-10 11:42:00 | ERROR | Traceback (most recent call last):
  File "/Users/ulisesv/Desktop/chewbacca/backend/api/src/services/people.py", line 13, in get_people
    results = get_people_pagination(page)
              ^^^^^^^^^^^^^^^^^^^^^^^^^^^
  File "/Users/ulisesv/Desktop/chewbacca/backend/api/src/controllers/people.py", line 20, in get_people_pagination
    cursor.execute("SELECT  id, name, height, mass, hairColor, gender, dob, img FROM people limit %s, %s;", (startat, perpage))
  File "/Library/Frameworks/Python.framework/Versions/3.12/lib/python3.12/site-packages/pymysql/cursors.py", line 153, in execute
    result = self._query(query)
             ^^^^^^^^^^^^^^^^^^
  File "/Library/Frameworks/Python.framework/Versions/3.12/lib/python3.12/site-packages/pymysql/cursors.py", line 322, in _query
    conn.query(q)
  File "/Library/Frameworks/Python.framework/Versions/3.12/lib/python3.12/site-packages/pymysql/connections.py", line 558, in query
    self._affected_rows = self._read_query_result(unbuffered=unbuffered)
                          ^^^^^^^^^^^^^^^^^^^^^^^^^^^^^^^^^^^^^^^^^^^^^^
  File "/Library/Frameworks/Python.framework/Versions/3.12/lib/python3.12/site-packages/pymysql/connections.py", line 822, in _read_query_result
    result.read()
  File "/Library/Frameworks/Python.framework/Versions/3.12/lib/python3.12/site-packages/pymysql/connections.py", line 1200, in read
    first_packet = self.connection._read_packet()
                   ^^^^^^^^^^^^^^^^^^^^^^^^^^^^^^
  File "/Library/Frameworks/Python.framework/Versions/3.12/lib/python3.12/site-packages/pymysql/connections.py", line 772, in _read_packet
    packet.raise_for_error()
  File "/Library/Frameworks/Python.framework/Versions/3.12/lib/python3.12/site-packages/pymysql/protocol.py", line 221, in raise_for_error
    err.raise_mysql_exception(self._data)
  File "/Library/Frameworks/Python.framework/Versions/3.12/lib/python3.12/site-packages/pymysql/err.py", line 143, in raise_mysql_exception
    raise errorclass(errno, errval)
pymysql.err.OperationalError: (1054, "Unknown column 'id' in 'field list'")

