2024-05-12 23:00:44 | ERROR | (2003, "Can't connect to MySQL server on 'mysql' ([Errno 8] nodename nor servname provided, or not known)")
2024-05-12 23:00:44 | ERROR | Traceback (most recent call last):
  File "/Library/Frameworks/Python.framework/Versions/3.12/lib/python3.12/site-packages/pymysql/connections.py", line 644, in connect
    sock = socket.create_connection(
           ^^^^^^^^^^^^^^^^^^^^^^^^^
  File "/Library/Frameworks/Python.framework/Versions/3.12/lib/python3.12/socket.py", line 828, in create_connection
    for res in getaddrinfo(host, port, 0, SOCK_STREAM):
               ^^^^^^^^^^^^^^^^^^^^^^^^^^^^^^^^^^^^^^^
  File "/Library/Frameworks/Python.framework/Versions/3.12/lib/python3.12/socket.py", line 963, in getaddrinfo
    for res in _socket.getaddrinfo(host, port, family, type, proto, flags):
               ^^^^^^^^^^^^^^^^^^^^^^^^^^^^^^^^^^^^^^^^^^^^^^^^^^^^^^^^^^^
socket.gaierror: [Errno 8] nodename nor servname provided, or not known

During handling of the above exception, another exception occurred:

Traceback (most recent call last):
  File "/Users/ulisesv/Desktop/chewbacca/backend/api/src/database/db_mysql.py", line 9, in get_connection
    return pymysql.connect(
           ^^^^^^^^^^^^^^^^
  File "/Library/Frameworks/Python.framework/Versions/3.12/lib/python3.12/site-packages/pymysql/connections.py", line 358, in __init__
    self.connect()
  File "/Library/Frameworks/Python.framework/Versions/3.12/lib/python3.12/site-packages/pymysql/connections.py", line 711, in connect
    raise exc
pymysql.err.OperationalError: (2003, "Can't connect to MySQL server on 'mysql' ([Errno 8] nodename nor servname provided, or not known)")

2024-05-12 23:00:44 | ERROR | cannot access local variable 'res' where it is not associated with a value
2024-05-12 23:00:44 | ERROR | Traceback (most recent call last):
  File "/Users/ulisesv/Desktop/chewbacca/backend/api/src/services/people.py", line 13, in get_people
    results = get_people_pagination(page)
              ^^^^^^^^^^^^^^^^^^^^^^^^^^^
  File "/Users/ulisesv/Desktop/chewbacca/backend/api/src/controllers/people.py", line 32, in get_people_pagination
    return res
           ^^^
UnboundLocalError: cannot access local variable 'res' where it is not associated with a value

2024-05-12 23:00:44 | ERROR | (2003, "Can't connect to MySQL server on 'mysql' ([Errno 8] nodename nor servname provided, or not known)")
2024-05-12 23:00:44 | ERROR | Traceback (most recent call last):
  File "/Library/Frameworks/Python.framework/Versions/3.12/lib/python3.12/site-packages/pymysql/connections.py", line 644, in connect
    sock = socket.create_connection(
           ^^^^^^^^^^^^^^^^^^^^^^^^^
  File "/Library/Frameworks/Python.framework/Versions/3.12/lib/python3.12/socket.py", line 828, in create_connection
    for res in getaddrinfo(host, port, 0, SOCK_STREAM):
               ^^^^^^^^^^^^^^^^^^^^^^^^^^^^^^^^^^^^^^^
  File "/Library/Frameworks/Python.framework/Versions/3.12/lib/python3.12/socket.py", line 963, in getaddrinfo
    for res in _socket.getaddrinfo(host, port, family, type, proto, flags):
               ^^^^^^^^^^^^^^^^^^^^^^^^^^^^^^^^^^^^^^^^^^^^^^^^^^^^^^^^^^^
socket.gaierror: [Errno 8] nodename nor servname provided, or not known

During handling of the above exception, another exception occurred:

Traceback (most recent call last):
  File "/Users/ulisesv/Desktop/chewbacca/backend/api/src/database/db_mysql.py", line 9, in get_connection
    return pymysql.connect(
           ^^^^^^^^^^^^^^^^
  File "/Library/Frameworks/Python.framework/Versions/3.12/lib/python3.12/site-packages/pymysql/connections.py", line 358, in __init__
    self.connect()
  File "/Library/Frameworks/Python.framework/Versions/3.12/lib/python3.12/site-packages/pymysql/connections.py", line 711, in connect
    raise exc
pymysql.err.OperationalError: (2003, "Can't connect to MySQL server on 'mysql' ([Errno 8] nodename nor servname provided, or not known)")

2024-05-12 23:00:44 | ERROR | cannot access local variable 'res' where it is not associated with a value
2024-05-12 23:00:44 | ERROR | Traceback (most recent call last):
  File "/Users/ulisesv/Desktop/chewbacca/backend/api/src/services/people.py", line 13, in get_people
    results = get_people_pagination(page)
              ^^^^^^^^^^^^^^^^^^^^^^^^^^^
  File "/Users/ulisesv/Desktop/chewbacca/backend/api/src/controllers/people.py", line 32, in get_people_pagination
    return res
           ^^^
UnboundLocalError: cannot access local variable 'res' where it is not associated with a value

2024-05-12 23:01:02 | ERROR | (2003, "Can't connect to MySQL server on 'mysql' ([Errno 8] nodename nor servname provided, or not known)")
2024-05-12 23:01:02 | ERROR | Traceback (most recent call last):
  File "/Library/Frameworks/Python.framework/Versions/3.12/lib/python3.12/site-packages/pymysql/connections.py", line 644, in connect
    sock = socket.create_connection(
           ^^^^^^^^^^^^^^^^^^^^^^^^^
  File "/Library/Frameworks/Python.framework/Versions/3.12/lib/python3.12/socket.py", line 828, in create_connection
    for res in getaddrinfo(host, port, 0, SOCK_STREAM):
               ^^^^^^^^^^^^^^^^^^^^^^^^^^^^^^^^^^^^^^^
  File "/Library/Frameworks/Python.framework/Versions/3.12/lib/python3.12/socket.py", line 963, in getaddrinfo
    for res in _socket.getaddrinfo(host, port, family, type, proto, flags):
               ^^^^^^^^^^^^^^^^^^^^^^^^^^^^^^^^^^^^^^^^^^^^^^^^^^^^^^^^^^^
socket.gaierror: [Errno 8] nodename nor servname provided, or not known

During handling of the above exception, another exception occurred:

Traceback (most recent call last):
  File "/Users/ulisesv/Desktop/chewbacca/backend/api/src/database/db_mysql.py", line 9, in get_connection
    return pymysql.connect(
           ^^^^^^^^^^^^^^^^
  File "/Library/Frameworks/Python.framework/Versions/3.12/lib/python3.12/site-packages/pymysql/connections.py", line 358, in __init__
    self.connect()
  File "/Library/Frameworks/Python.framework/Versions/3.12/lib/python3.12/site-packages/pymysql/connections.py", line 711, in connect
    raise exc
pymysql.err.OperationalError: (2003, "Can't connect to MySQL server on 'mysql' ([Errno 8] nodename nor servname provided, or not known)")

2024-05-12 23:01:02 | ERROR | cannot access local variable 'res' where it is not associated with a value
2024-05-12 23:01:02 | ERROR | Traceback (most recent call last):
  File "/Users/ulisesv/Desktop/chewbacca/backend/api/src/services/people.py", line 13, in get_people
    results = get_people_pagination(page)
              ^^^^^^^^^^^^^^^^^^^^^^^^^^^
  File "/Users/ulisesv/Desktop/chewbacca/backend/api/src/controllers/people.py", line 32, in get_people_pagination
    return res
           ^^^
UnboundLocalError: cannot access local variable 'res' where it is not associated with a value

2024-05-12 23:01:02 | ERROR | (2003, "Can't connect to MySQL server on 'mysql' ([Errno 8] nodename nor servname provided, or not known)")
2024-05-12 23:01:02 | ERROR | Traceback (most recent call last):
  File "/Library/Frameworks/Python.framework/Versions/3.12/lib/python3.12/site-packages/pymysql/connections.py", line 644, in connect
    sock = socket.create_connection(
           ^^^^^^^^^^^^^^^^^^^^^^^^^
  File "/Library/Frameworks/Python.framework/Versions/3.12/lib/python3.12/socket.py", line 828, in create_connection
    for res in getaddrinfo(host, port, 0, SOCK_STREAM):
               ^^^^^^^^^^^^^^^^^^^^^^^^^^^^^^^^^^^^^^^
  File "/Library/Frameworks/Python.framework/Versions/3.12/lib/python3.12/socket.py", line 963, in getaddrinfo
    for res in _socket.getaddrinfo(host, port, family, type, proto, flags):
               ^^^^^^^^^^^^^^^^^^^^^^^^^^^^^^^^^^^^^^^^^^^^^^^^^^^^^^^^^^^
socket.gaierror: [Errno 8] nodename nor servname provided, or not known

During handling of the above exception, another exception occurred:

Traceback (most recent call last):
  File "/Users/ulisesv/Desktop/chewbacca/backend/api/src/database/db_mysql.py", line 9, in get_connection
    return pymysql.connect(
           ^^^^^^^^^^^^^^^^
  File "/Library/Frameworks/Python.framework/Versions/3.12/lib/python3.12/site-packages/pymysql/connections.py", line 358, in __init__
    self.connect()
  File "/Library/Frameworks/Python.framework/Versions/3.12/lib/python3.12/site-packages/pymysql/connections.py", line 711, in connect
    raise exc
pymysql.err.OperationalError: (2003, "Can't connect to MySQL server on 'mysql' ([Errno 8] nodename nor servname provided, or not known)")

2024-05-12 23:01:02 | ERROR | cannot access local variable 'res' where it is not associated with a value
2024-05-12 23:01:02 | ERROR | Traceback (most recent call last):
  File "/Users/ulisesv/Desktop/chewbacca/backend/api/src/services/people.py", line 13, in get_people
    results = get_people_pagination(page)
              ^^^^^^^^^^^^^^^^^^^^^^^^^^^
  File "/Users/ulisesv/Desktop/chewbacca/backend/api/src/controllers/people.py", line 32, in get_people_pagination
    return res
           ^^^
UnboundLocalError: cannot access local variable 'res' where it is not associated with a value

